<?xml version="1.0"?>
<!-- =================================================================================== -->
<!-- |    This document was autogenerated by xacro from b21.xacro                      | -->
<!-- |    EDITING THIS FILE BY HAND IS NOT RECOMMENDED                                 | -->
<!-- =================================================================================== -->
<robot name="lewis"
  xmlns:controller="http://playerstage.sourceforge.net/gazebo/xmlschema/#controller"
  xmlns:interface="http://playerstage.sourceforge.net/gazebo/xmlschema/#interface"
  xmlns:sensor="http://playerstage.sourceforge.net/gazebo/xmlschema/#sensor">
  <link name="base_link">
    <visual>
      <origin xyz="0 0 .15"/>
      <geometry>
        <cylinder length="0.3" radius="0.1"/>
      </geometry>
      <material name="black">
        <color rgba="0 0 0 1"/>
      </material>
    </visual>
    <collision>
      <origin xyz="0 0 .15"/>
      <geometry>
        <cylinder length="0.3" radius="0.1"/>
      </geometry>
    </collision>
  </link>
  <link name="body">
    <visual>
      <origin xyz="0 0 .265"/>
      <geometry>
        <cylinder length="0.53" radius="0.25"/>
      </geometry>
      <material name="lewisred">
        <color rgba="1 0 0 1"/>
      </material>
    </visual>
    <collision>
      <origin xyz="0 0 .265"/>
      <geometry>
        <cylinder length="0.53" radius="0.25"/>
      </geometry>
    </collision>
  </link>
  <joint name="base_to_body" type="fixed">
    <origin xyz="0 0 .40"/>
    <parent link="base_link"/>
    <child link="body"/>
  </joint>
  <link name="base">
    <visual>
      <origin xyz="0 0 .15"/>
      <geometry>
        <cylinder length="0.3" radius="0.26"/>
      </geometry>
      <material name="lewisred"/>
    </visual>
    <collision>
      <origin xyz="0 0 .15"/>
      <geometry>
        <cylinder length="0.3" radius="0.26"/>
      </geometry>
    </collision>
  </link>
  <joint name="lewis_twist" type="continuous">
    <parent link="body"/>
    <child link="base"/>
    <origin xyz="0 0 -.40"/>
    <axis xyz="0 0 1"/>
  </joint>
  <link name="connector">
    <visual>
      <origin/>
      <geometry>
        <box size=".15 .30 .1"/>
      </geometry>
      <material name="black"/>
    </visual>
    <collision>
      <origin/>
      <geometry>
        <box size=".15 .30 .1"/>
      </geometry>
    </collision>
  </link>
  <joint name="connect" type="fixed">
    <origin xyz="-0.12 0 -.05"/>
    <parent link="body"/>
    <child link="connector"/>
  </joint>
  <link name="laserbase">
    <visual>
      <origin/>
      <geometry>
        <box size=".04 .04 .04"/>
      </geometry>
      <material name="gray">
        <color rgba=".8 .8 .8 1"/>
      </material>
    </visual>
    <collision>
      <origin/>
      <geometry>
        <box size=".04 .04 .04"/>
      </geometry>
    </collision>
  </link>
  <joint name="tolaserbase" type="fixed">
    <origin xyz="-0.29 0 -.08"/>
    <parent link="body"/>
    <child link="laserbase"/>
  </joint>
  <link name="laser">
    <visual>
      <origin/>
      <geometry>
        <cylinder length="0.03" radius="0.02"/>
      </geometry>
      <material name="black"/>
    </visual>
    <collision>
      <origin/>
      <geometry>
        <cylinder length="0.03" radius="0.02"/>
      </geometry>
    </collision>
  </link>
  <joint name="tolaser" type="fixed">
    <origin xyz="0 0 .035"/>
    <parent link="laserbase"/>
    <child link="laser"/>
  </joint>
  <link name="bodytop">
    <visual>
      <origin/>
      <geometry>
        <cylinder length="0.02" radius="0.25"/>
      </geometry>
      <material name="black"/>
    </visual>
    <collision>
      <origin/>
      <geometry>
        <cylinder length="0.02" radius="0.25"/>
      </geometry>
    </collision>
  </link>
  <joint name="totop" type="fixed">
    <origin xyz="0 0 .54"/>
    <parent link="body"/>
    <child link="bodytop"/>
  </joint>
  <link name="leftbrace">
    <visual>
      <origin/>
      <geometry>
        <box size="0.1 .01 .13"/>
      </geometry>
      <material name="black"/>
    </visual>
    <collision>
      <origin/>
      <geometry>
        <box size="0.1 .01 .13"/>
      </geometry>
    </collision>
  </link>
  <joint name="toleftbrace" type="fixed">
    <origin xyz="0 0.20 .075"/>
    <parent link="bodytop"/>
    <child link="leftbrace"/>
  </joint>
  <link name="rightbrace">
    <visual>
      <origin/>
      <geometry>
        <box size="0.1 .01 .13"/>
      </geometry>
      <material name="black"/>
    </visual>
    <collision>
      <origin/>
      <geometry>
        <box size="0.1 .01 .13"/>
      </geometry>
    </collision>
  </link>
  <joint name="torightbrace" type="fixed">
    <origin xyz="0 -0.20 .075"/>
    <parent link="bodytop"/>
    <child link="rightbrace"/>
  </joint>
  <link name="platform">
    <visual>
      <origin/>
      <geometry>
        <box size="0.30 .50 .06"/>
      </geometry>
      <material name="lewisred"/>
    </visual>
    <collision>
      <origin/>
      <geometry>
        <box size="0.30 .50 .06"/>
      </geometry>
    </collision>
  </link>
  <joint name="toplatform" type="fixed">
    <origin xyz="0.1 0 .17"/>
    <parent link="bodytop"/>
    <child link="platform"/>
  </joint>
  <link name="graybase">
    <visual>
      <origin/>
      <geometry>
        <box size="0.14 .25 .005"/>
      </geometry>
      <material name="gray"/>
    </visual>
    <collision>
      <origin/>
      <geometry>
        <box size="0.14 .25 .005"/>
      </geometry>
    </collision>
  </link>
  <joint name="tograybase" type="fixed">
    <origin xyz="0.02 0 .0325"/>
    <parent link="platform"/>
    <child link="graybase"/>
  </joint>
  <link name="post1">
    <visual>
      <origin/>
      <geometry>
        <cylinder length="0.155" radius="0.005"/>
      </geometry>
      <material name="gray"/>
    </visual>
    <collision>
      <origin/>
      <geometry>
        <cylinder length="0.155" radius="0.005"/>
      </geometry>
    </collision>
  </link>
  <joint name="topost1" type="fixed">
    <origin xyz="0.03 0.115 .08"/>
    <parent link="graybase"/>
    <child link="post1"/>
  </joint>
  <link name="post2">
    <visual>
      <origin/>
      <geometry>
        <cylinder length="0.155" radius="0.005"/>
      </geometry>
      <material name="gray"/>
    </visual>
    <collision>
      <origin/>
      <geometry>
        <cylinder length="0.155" radius="0.005"/>
      </geometry>
    </collision>
  </link>
  <joint name="topost2" type="fixed">
    <origin xyz="0.03 -0.115 .08"/>
    <parent link="graybase"/>
    <child link="post2"/>
  </joint>
  <link name="post3">
    <visual>
      <origin/>
      <geometry>
        <cylinder length="0.155" radius="0.005"/>
      </geometry>
      <material name="gray"/>
    </visual>
    <collision>
      <origin/>
      <geometry>
        <cylinder length="0.155" radius="0.005"/>
      </geometry>
    </collision>
  </link>
  <joint name="topost3" type="fixed">
    <origin xyz="-0.03 0.115 .08"/>
    <parent link="graybase"/>
    <child link="post3"/>
  </joint>
  <link name="post4">
    <visual>
      <origin/>
      <geometry>
        <cylinder length="0.155" radius="0.005"/>
      </geometry>
      <material name="gray"/>
    </visual>
    <collision>
      <origin/>
      <geometry>
        <cylinder length="0.155" radius="0.005"/>
      </geometry>
    </collision>
  </link>
  <joint name="topost4" type="fixed">
    <origin xyz="-0.03 -0.115 .08"/>
    <parent link="graybase"/>
    <child link="post4"/>
  </joint>
  <link name="graytop">
    <visual>
      <origin/>
      <geometry>
        <box size="0.135 .25 .005"/>
      </geometry>
      <material name="gray"/>
    </visual>
    <collision>
      <origin/>
      <geometry>
        <box size="0.135 .25 .005"/>
      </geometry>
    </collision>
  </link>
  <joint name="tograytop" type="fixed">
    <origin xyz="0.02 0 .155"/>
    <parent link="graybase"/>
    <child link="graytop"/>
  </joint>
  <link name="ptu_base">
    <visual>
      <origin xyz="0 0.015 0"/>
      <geometry>
        <box size="0.04 .07 .05"/>
      </geometry>
      <material name="black"/>
    </visual>
    <collision>
      <origin xyz="0 0.015 0"/>
      <geometry>
        <box size="0.04 .07 .05"/>
      </geometry>
    </collision>
  </link>
  <joint name="toptubase" type="fixed">
    <origin xyz="0 -0.0075 .0275"/>
    <parent link="graytop"/>
    <child link="ptu_base"/>
  </joint>
  <link name="ptu_piece">
    <visual>
      <origin/>
      <geometry>
        <box size="0.04 .04 .06"/>
      </geometry>
      <material name="black"/>
    </visual>
    <collision>
      <origin/>
      <geometry>
        <box size="0.04 .04 .06"/>
      </geometry>
    </collision>
  </link>
  <joint name="pan" type="continuous">
    <origin xyz="0 0 .055"/>
    <axis xyz="0 0 1"/>
    <parent link="ptu_base"/>
    <child link="ptu_piece"/>
  </joint>
  <link name="ptu_mount">
    <visual>
      <origin/>
      <geometry>
        <box size="0.04 .27 .03"/>
      </geometry>
      <material name="gray"/>
    </visual>
    <collision>
      <origin/>
      <geometry>
        <box size="0.04 .27 .03"/>
      </geometry>
    </collision>
  </link>
  <joint name="tilt" type="continuous">
    <origin xyz="0 0 .065"/>
    <axis xyz="0 1 0"/>
    <parent link="ptu_piece"/>
    <child link="ptu_mount"/>
  </joint>
  <link name="lefteye">
    <visual>
      <geometry>
        <sphere radius="0.04"/>
      </geometry>
      <material name="black"/>
    </visual>
    <collision>
      <geometry>
        <sphere radius="0.04"/>
      </geometry>
    </collision>
  </link>
  <joint name="tolefteye" type="fixed">
    <origin xyz="0.05 0.11 .02"/>
    <parent link="ptu_mount"/>
    <child link="lefteye"/>
  </joint>
  <link name="righteye">
    <visual>
      <geometry>
        <sphere radius="0.04"/>
      </geometry>
      <material name="black"/>
    </visual>
    <collision>
      <geometry>
        <sphere radius="0.04"/>
      </geometry>
    </collision>
  </link>
  <joint name="torighteye" type="fixed">
    <origin xyz="0.05 -0.11 .02"/>
    <parent link="ptu_mount"/>
    <child link="righteye"/>
  </joint>
</robot>
