
<!-- =================================================================================== -->
<!-- |    This document was autogenerated by xacro from /home/c703101/ros_ws/src/rekooh-robot/rekooh_description/urdf/rekooh.xacro | -->
<!-- |    EDITING THIS FILE BY HAND IS NOT RECOMMENDED                                 | -->
<!-- =================================================================================== -->
<robot name="rekooh"
  xmlns:xacro="http://ros.org/wiki/xacro">
  <material name="White">
    <color rgba="1 1 1 1"/>
  </material>
  <material name="LightGrey">
    <color rgba="0.85 0.85 0.85 1"/>
  </material>
  <material name="Black">
    <color rgba="0 0 0 1"/>
  </material>
  <material name="Kuka/DarkGrey">
    <color rgba="0.3 0.3 0.3 1.0"/>
  </material>
  <material name="Kuka/LightGrey">
    <color rgba="0.8 0.8 0.8 1.0"/>
  </material>
  <material name="Kuka/Red">
    <color rgba="0.3 0.3 0.3 1.0"/>
  </material>
  <material name="Kuka/Black">
    <color rgba="0 0 0 1.0"/>
  </material>
  <material name="Kuka/Orange">
    <color rgba="1.0 0.487 0 1.0"/>
  </material>
  <material name="Kuka/Silver">
    <color rgba="1.0 1.0 1.0 1.0"/>
  </material>
  <material name="Kuka/Grey">
    <color rgba="0.7 0.7 0.7 1.0"/>
  </material>
  <material name="Kuka/Blue">
    <color rgba="0.0 0.0 0.8 1.0"/>
  </material>
  <!-- reflex to stiffness -->
  <material name="SoftHand/LightGrey">
    <color rgba="0.7 0.7 0.7 1.0"/>
  </material>
  <material name="SoftHand/DarkGrey">
    <color rgba="0.4 0.4 0.4 1.0"/>
  </material>
  <material name="SoftHand/Black">
    <color rgba="0.0 0.0 0.0 1.0"/>
  </material>
  <material name="SoftHand/DarkGolden">
    <color rgba="0.4 0.4 0.3 1.0"/>
  </material>
  <material name="SoftHand/Blue">
    <color rgba="0.0 0.0 0.8 0.9"/>
  </material>
  <material name="SoftHand/LightBlue">
    <color rgba="0.0 0.4 1.0 0.5"/>
  </material>
  <!-- <xacro:insert_block name="gazebo_friction_properties"/> -->
  <!-- <xacro:insert_block name="gazebo_other_properties"/> -->
  <!-- NOTE: inertia values are approximated using meshlab and only using the significant elements -->
  <!-- from http://answers.ros.org/question/11350/is-there-any-way-to-calculate-inertial-property-of-a-robot-to-simulate-it-in-gazebo/s
    One general rule of thumb I use for checking my inertia tensors is: If total mass of the rigid body is m, and the dimension of the corresponding body is d, then check to see if ixx, iyy, izz are near m*(d/2)^2.

    This is by no means correct, but a sanity check to make sure the moment of inertia are the right order of magnitudes, so the model behaves somewhat physically realistically.
    -->
  <material name="Schunk/LightGrey">
    <color rgba="0.7 0.7 0.7 1.0"/>
  </material>
  <material name="Schunk/DarkGrey">
    <color rgba="0.4 0.4 0.4 1.0"/>
  </material>
  <material name="Schunk/Black">
    <color rgba="0.0 0.0 0.0 1.0"/>
  </material>
  <material name="Schunk/DarkGolden">
    <color rgba="0.4 0.4 0.3 1.0"/>
  </material>
  <material name="Schunk/Blue">
    <color rgba="0.0 0.0 0.8 1.0"/>
  </material>
  <material name="KIT/White">
    <color rgba="1 1 1 1.0"/>
  </material>
  <material name="KIT/DarkGrey">
    <color rgba="0.3 0.3 0.3 1.0"/>
  </material>
  <material name="KIT/LightGrey">
    <color rgba="0.8 0.8 0.8 1.0"/>
  </material>
  <material name="KIT/Red">
    <color rgba="0.3 0.3 0.3 1.0"/>
  </material>
  <material name="KIT/Black">
    <color rgba="0 0 0 1.0"/>
  </material>
  <material name="KIT/Orange">
    <color rgba="1.0 0.487 0 1.0"/>
  </material>
  <material name="KIT/Silver">
    <color rgba="1.0 1.0 1.0 1.0"/>
  </material>
  <material name="KIT/Grey">
    <color rgba="0.7 0.7 0.7 1.0"/>
  </material>
  <material name="KIT/Blue">
    <color rgba="0.0 0.0 0.8 1.0"/>
  </material>
  <material name="KIT/HandGray">
    <color rgba="0.953 0.996 0.694 1.0"/>
  </material>
  <material name="KIT/SickBlue">
    <color rgba="0.3058 0.5921 0.7294 1.0"/>
  </material>
  <!-- NOTE: inertia values are approximated using meshlab and only using the significant elements -->
  <!-- from http://answers.ros.org/question/11350/is-there-any-way-to-calculate-inertial-property-of-a-robot-to-simulate-it-in-gazebo/s
    One general rule of thumb I use for checking my inertia tensors is: If total mass of the rigid body is m, and the dimension of the corresponding body is d, then check to see if ixx, iyy, izz are near m*(d/2)^2.

    This is by no means correct, but a sanity check to make sure the moment of inertia are the right order of magnitudes, so the model behaves somewhat physically realistically.
    -->
  <!-- real inertia for the head are still required -->
  <link name="world" />
  <joint name="base_joint" type="fixed">
    <origin rpy="0 0 0" xyz="0 0 0.790"/>
    <parent link="world"/>
    <child link="base_link"/>
  </joint>
  <link name="base_link">
    <origin rpy="0 0 0" xyz="0 0 0.790" />
  </link>
  <!-- TABLE -->
  <joint name="base_link_table_base_joint" type="fixed">
    <origin rpy="0 0 0" xyz="0 0 0"/>
    <parent link="base_link" />
    <child link="table_base_link"/>
  </joint>
  <link name="table_base_link" />
  <joint name="base_link_table_back_joint" type="fixed">
    <parent link="table_base_link"/>
    <child link="table_back_link"/>
  </joint>
  <link name="table_back_link">
    <inertial>
      <origin xyz="0 0 0"/>
      <mass value="4.0"/>
      <inertia ixx="0.04" ixy="0.0" ixz="0.0" iyy="0.04" iyz="0.0" izz="0.04"/>
    </inertial>
    <visual>
      <origin xyz="-0.12 0.0 -0.06"/>
      <geometry>
        <box size="0.24 2.0 0.12" />
      </geometry>
      <material name="LightGrey"/>
    </visual>
    <collision>
      <origin xyz="-0.12 0.0 -0.06"/>
      <geometry>
        <box size="0.24 2.0 0.12"/>
      </geometry>
      <material name="LightGrey" />
    </collision>
  </link>
  <gazebo reference="table_back_link">
    <material>Gazebo/Grey</material>
  </gazebo>
  <joint name="base_link_table_left_joint" type="fixed">
    <parent link="table_base_link"/>
    <child link="table_left_link"/>
  </joint>
  <link name="table_left_link">
    <inertial>
      <origin xyz="0 0 0" />
      <mass value="4.0"/>
      <inertia ixx="0.04" ixy="0.0" ixz="0.0" iyy="0.04" iyz="0.0" izz="0.04"/>
    </inertial>
    <visual>
      <origin xyz="0.5 1.02 -0.06"/>
      <geometry>
        <box size="1.48 0.04 0.12"/>
      </geometry>
      <material name="LightGrey"/>
    </visual>
    <collision>
      <origin xyz="0.5 1.02 -0.06"/>
      <geometry>
        <box size="1.48 0.04 0.12"/>
      </geometry>
      <material name="LightGrey"/>
    </collision>
  </link>
  <gazebo reference="table_left_link">
    <material>Gazebo/Grey</material>
  </gazebo>
  <joint name="base_link_table_right_joint" type="fixed">
    <parent link="table_base_link"/>
    <child link="table_right_link" />
  </joint>
  <link name="table_right_link">
    <inertial>
      <origin xyz="0 0 0"/>
      <mass value="4.0"/>
      <inertia ixx="0.04" ixy="0.0" ixz="0.0" iyy="0.04" iyz="0.0" izz="0.04"/>
    </inertial>
    <visual>
      <origin xyz="0.5 -1.02 -0.06"/>
      <geometry>
        <box size="1.48 0.04 0.12"/>
      </geometry>
      <material name="LightGrey" />
    </visual>
    <collision>
      <origin xyz="0.5 -1.02 -0.06"/>
      <geometry>
        <box size="1.48 0.04 0.12"/>
      </geometry>
      <material name="LightGrey"/>
    </collision>
  </link>
  <gazebo reference="table_right_link">
    <material>Gazebo/Grey</material>
  </gazebo>
  <joint name="base_link_table_front_joint" type="fixed">
    <parent link="table_base_link" />
    <child link="table_front_link"/>
  </joint>
  <link name="table_front_link">
    <inertial>
      <origin xyz="0 0 0"/>
      <mass value="4.0"/>
      <inertia ixx="0.04" ixy="0.0" ixz="0.0" iyy="0.04" iyz="0.0" izz="0.04"/>
    </inertial>
    <visual>
      <origin xyz="1.22 0.0 -0.06"/>
      <geometry>
        <box size="0.04 2.0 0.12"/>
      </geometry>
      <material name="LightGrey"/>
    </visual>
    <collision>
      <origin xyz="1.22 0.0 -0.06"/>
      <geometry>
        <box size="0.04 2.0 0.12" />
      </geometry>
      <material name="LightGrey"/>
    </collision>
  </link>
  <gazebo reference="table_front_link">
    <material>Gazebo/Grey</material>
  </gazebo>
  <joint name="base_link_table_surface_joint" type="fixed">
    <parent link="table_base_link"/>
    <child link="table_surface_link" />
  </joint>
  <link name="table_surface_link">
    <inertial>
      <origin xyz="0 0 0"/>
      <mass value="4.0"/>
      <inertia ixx="0.04" ixy="0.0" ixz="0.0" iyy="0.04" iyz="0.0" izz="0.04"/>
    </inertial>
    <visual>
      <origin xyz="0.6 0.0 -0.06"/>
      <geometry>
        <box size="1.2 2.0 0.12"/>
      </geometry>
      <material name="White"/>
    </visual>
    <collision>
      <origin xyz="0.6 0.0 -0.06"/>
      <geometry>
        <box size="1.2 2.0 0.12"/>
      </geometry>
    </collision>
  </link>
  <gazebo reference="table_surface_link">
    <material>Gazebo/White</material>
  </gazebo>
  <joint name="leg_0_joint" type="fixed">
    <origin xyz="-0.1 -0.98 -0.455"/>
    <parent link="table_base_link"/>
    <child link="leg_0_link"/>
  </joint>
  <link name="leg_0_link">
    <inertial>
      <origin xyz="0 0 0"/>
      <mass value="4.0"/>
      <inertia ixx="0.04" ixy="0.0" ixz="0.0" iyy="0.04" iyz="0.0" izz="0.04"/>
    </inertial>
    <visual>
      <geometry>
        <box size="0.12 -0.04 0.67"/>
      </geometry>
      <material name="LightGrey"/>
    </visual>
    <collision>
      <geometry>
        <box size="0.12 -0.04 0.67"/>
      </geometry>
    </collision>
  </link>
  <gazebo reference="leg_0_link">
    <!-- <selfCollide>true</selfCollide> -->
    <material>Gazebo/Grey</material>
  </gazebo>
  <joint name="leg_1_joint" type="fixed">
    <origin xyz="-0.1 0.98 -0.455"/>
    <parent link="table_base_link" />
    <child link="leg_1_link"/>
  </joint>
  <link name="leg_1_link">
    <inertial>
      <origin xyz="0 0 0"/>
      <mass value="4.0"/>
      <inertia ixx="0.04" ixy="0.0" ixz="0.0" iyy="0.04" iyz="0.0" izz="0.04"/>
    </inertial>
    <visual>
      <geometry>
        <box size="0.12 -0.04 0.67"/>
      </geometry>
      <material name="LightGrey"/>
    </visual>
    <collision>
      <geometry>
        <box size="0.12 -0.04 0.67"/>
      </geometry>
    </collision>
  </link>
  <gazebo reference="leg_1_link">
    <!-- <selfCollide>true</selfCollide> -->
    <material>Gazebo/Grey</material>
  </gazebo>
  <joint name="leg_2_joint" type="fixed">
    <origin xyz="1.14 0.98 -0.455"/>
    <parent link="table_base_link"/>
    <child link="leg_2_link"/>
  </joint>
  <link name="leg_2_link">
    <inertial>
      <origin xyz="0 0 0"/>
      <mass value="4.0"/>
      <inertia ixx="0.04" ixy="0.0" ixz="0.0" iyy="0.04" iyz="0.0" izz="0.04"/>
    </inertial>
    <visual>
      <geometry>
        <box size="0.12 -0.04 0.67"/>
      </geometry>
      <material name="LightGrey"/>
    </visual>
    <collision>
      <geometry>
        <box size="0.12 -0.04 0.67"/>
      </geometry>
    </collision>
  </link>
  <gazebo reference="leg_2_link">
    <!-- <selfCollide>true</selfCollide> -->
    <material>Gazebo/Grey</material>
  </gazebo>
  <joint name="leg_3_joint" type="fixed">
    <origin xyz="1.14 -0.98 -0.455"/>
    <parent link="table_base_link"/>
    <child link="leg_3_link"/>
  </joint>
  <link name="leg_3_link">
    <inertial>
      <origin xyz="0 0 0"/>
      <mass value="4.0"/>
      <inertia ixx="0.04" ixy="0.0" ixz="0.0" iyy="0.04" iyz="0.0" izz="0.04"/>
    </inertial>
    <visual>
      <geometry>
        <box size="0.12 -0.04 0.67"/>
      </geometry>
      <material name="LightGrey" />
    </visual>
    <collision>
      <geometry>
        <box size="0.12 -0.04 0.67"/>
      </geometry>
    </collision>
  </link>
  <gazebo reference="leg_3_link">
    <!-- <selfCollide>true</selfCollide> -->
    <material>Gazebo/Grey</material>
  </gazebo>
  <material name="table_realsense_aluminum">
    <color rgba="0.5 0.5 0.5 1"/>
  </material>
  <!-- camera body, with origin at bottom screw mount -->
  <joint name="table_realsense_camera_joint" type="fixed">
    <origin rpy="0 1.57079632679 0" xyz="0.59 0.0 1.56"/>
    <parent link="base_link"/>
    <child link="table_realsense_camera_link"/>
  </joint>
  <link name="table_realsense_camera_link">
    <visual>
      <origin rpy="1.57079632679 0 1.57079632679" xyz="0.0149 0.0 0.0125"/>
      <geometry>
        <!-- <box size="${d435_cam_width} ${d435_cam_height} ${d435_cam_depth}" /> -->
        <mesh filename=""/>
      </geometry>
      <material name="table_realsense_aluminum"/>
    </visual>
    <collision>
      <origin rpy="0 0 0" xyz="0.0 0.0 0.0125" />
      <geometry>
        <box size="0.02505 0.09 0.025"/>
      </geometry>
    </collision>
    <inertial>
      <!-- The following are not reliable values, and should not be used for modeling -->
      <mass value="0.564"/>
      <origin xyz="0 0 0"/>
      <inertia ixx="0.003881243" ixy="0.0" ixz="0.0" iyy="0.000498940" iyz="0.0" izz="0.003879257"/>
    </inertial>
  </link>
  <!-- camera depth joints and links -->
  <joint name="table_realsense_camera_depth_joint" type="fixed">
    <origin rpy="0 0 0" xyz="0.0149 0.0175 0.0125"/>
    <parent link="table_realsense_camera_link"/>
    <child link="table_realsense_camera_depth_frame" />
  </joint>
  <link name="table_realsense_camera_depth_frame"/>
  <joint name="table_realsense_camera_depth_optical_joint" type="fixed">
    <origin rpy="-1.57079632679 0 -1.57079632679" xyz="0 0 0"/>
    <parent link="table_realsense_camera_depth_frame" />
    <child link="table_realsense_camera_depth_optical_frame"/>
  </joint>
  <link name="table_realsense_camera_depth_optical_frame"/>
  <!-- camera left IR joints and links -->
  <joint name="table_realsense_camera_left_ir_joint" type="fixed">
    <origin rpy="0 0 0" xyz="0 0.0 0"/>
    <parent link="table_realsense_camera_depth_frame"/>
    <child link="table_realsense_camera_left_ir_frame" />
  </joint>
  <link name="table_realsense_camera_left_ir_frame"/>
  <joint name="table_realsense_camera_left_ir_optical_joint" type="fixed">
    <origin rpy="-1.57079632679 0 -1.57079632679" xyz="0 0 0"/>
    <parent link="table_realsense_camera_left_ir_frame" />
    <child link="table_realsense_camera_left_ir_optical_frame"/>
  </joint>
  <link name="table_realsense_camera_left_ir_optical_frame"/>
  <!-- camera right IR joints and links -->
  <joint name="table_realsense_camera_right_ir_joint" type="fixed">
    <origin rpy="0 0 0" xyz="0 -0.05 0"/>
    <parent link="table_realsense_camera_depth_frame"/>
    <child link="table_realsense_camera_right_ir_frame" />
  </joint>
  <link name="table_realsense_camera_right_ir_frame"/>
  <joint name="table_realsense_camera_right_ir_optical_joint" type="fixed">
    <origin rpy="-1.57079632679 0 -1.57079632679" xyz="0 0 0"/>
    <parent link="table_realsense_camera_right_ir_frame" />
    <child link="table_realsense_camera_right_ir_optical_frame"/>
  </joint>
  <link name="table_realsense_camera_right_ir_optical_frame"/>
  <!-- camera color joints and links -->
  <joint name="table_realsense_camera_color_joint" type="fixed">
    <origin rpy="0 0 0" xyz="0 0.015 0"/>
    <parent link="table_realsense_camera_depth_frame"/>
    <child link="table_realsense_camera_color_frame" />
  </joint>
  <link name="table_realsense_camera_color_frame"/>
  <joint name="table_realsense_camera_color_optical_joint" type="fixed">
    <origin rpy="-1.57079632679 0 -1.57079632679" xyz="0 0 0"/>
    <parent link="table_realsense_camera_color_frame" />
    <child link="table_realsense_camera_color_optical_frame"/>
  </joint>
  <link name="table_realsense_camera_color_optical_frame"/>
  <joint name="left_arm_base_plate_joint" type="fixed">
    <origin rpy="0 0 0" xyz="-0.130 0.353 0.007525"/>
    <parent link="base_link"/>
    <child link="left_arm_base_plate_link" />
  </joint>
  <link name="left_arm_base_plate_link">
    <inertial>
      <origin xyz="0 0 0"/>
      <mass value="2.0"/>
      <inertia ixx="0.02" ixy="0.0" ixz="0.0" iyy="0.02" iyz="0.0" izz="0.02"/>
    </inertial>
    <visual>
      <geometry>
        <box size="0.275 0.275 0.0155"/>
      </geometry>
      <material name="LightGrey"/>
    </visual>
    <collision>
      <geometry>
        <box size="0.275 0.275 0.0155"/>
      </geometry>
    </collision>
  </link>
  <gazebo reference="left_arm_base_plate_link">
    <!-- <selfCollide>true</selfCollide> -->
    <material>Gazebo/Grey</material>
  </gazebo>
  <!-- First (shoulder) element of the arm. Fixed to its parent. -->
  <joint name="base_link_left_arm_base_joint" type="fixed">
    <origin rpy="0 0 3.14159265359" xyz="-0.130 0.353 0.0155"/>
    <!-- <origin rpy="0 0 0" xyz="0 0 0"/> -->
    <parent link="base_link"/>
    <child link="calib_left_arm_base_link" />
  </joint>
  <!-- In the original setting the arm was rotated around 180 degrees around the z axis because the point at the arm base, where the cables are located should point to the direction of the positive x axis of the arm reference frame. This link is used to correct that -->
  <link name="calib_left_arm_base_link" />
  <!-- Rotate arm around 180 degrees along z axis -->
  <joint name="calib_left_arm_base_joint" type="fixed">
    <!-- cahnges <origin xyz="0 0 0" rpy="0 0 ${M_PI}" /> -->
    <origin rpy="0 0 0" xyz="0 0 0"/>
    <parent link="calib_left_arm_base_link" />
    <child link="left_arm_base_link"/>
  </joint>
  <link name="left_arm_base_link">
    <inertial>
      <mass value="2.0"/>
      <origin xyz="0 0 0.055" />
      <inertia ixx="0.00381666666667" ixy="0" ixz="0" iyy="0.0036" iyz="0" izz="0.00381666666667"/>
    </inertial>
    <visual>
      <origin rpy="0 0 3.14159265359" xyz="0 0 0"/>
      <geometry>
        <mesh filename=""/>
      </geometry>
      <material name="Kuka/Orange"/>
    </visual>
    <collision>
      <origin rpy="0 0 3.14159265359" xyz="0 0 0.055"/>
      <geometry>
        <cylinder length="0.11" radius="0.07"/>
      </geometry>
    </collision>
  </link>
  <!-- Second segment of the arm. Joint along z-axis -->
  <joint name="left_arm_a1_joint" type="revolute">
    <origin rpy="0 0 0" xyz="0 0 0.11"/>
    <axis xyz="0 0 1"/>
    <limit effort="176" lower="-2.96705972839" upper="2.96705972839" velocity="1.91986217719"/>
    <dynamics damping="1.0" friction="10.0" />
    <parent link="left_arm_base_link"/>
    <child link="left_arm_1_link" />
  </joint>
  <joint name="left_arm_a1_joint_stiffness" type="revolute">
    <axis xyz="0 0 1"/>
    <limit effort="0" lower="0" upper="5000" velocity="20000"/>
    <safety_controller k_position="30" k_velocity="30" soft_lower_limit="0" soft_upper_limit="5000"/>
    <parent link="left_arm_base_link" />
    <child link="left_arm_1_link_dummy"/>
  </joint>
  <link name="left_arm_1_link_dummy" />
  <link name="left_arm_1_link">
    <inertial>
      <mass value="2.35" />
      <origin rpy="0 0 0" xyz="0 -0.06 0.130"/>
      <inertia ixx="0.0160583333333" ixy="0" ixz="0" iyy="0.003525" iyz="0" izz="0.0139433333333"/>
    </inertial>
    <visual>
      <origin rpy="0 0 3.14159265359" xyz="0 0 -0.008" />
      <geometry>
        <mesh filename=""/>
      </geometry>
      <material name="Kuka/Orange"/>
    </visual>
    <collision>
      <origin rpy="0 0 0" xyz="0 0 0.0"/>
      <geometry>
        <sphere radius="0.07"/>
      </geometry>
    </collision>
    <collision>
      <origin rpy="0 0 0" xyz="0 0.06 0.2"/>
      <geometry>
        <sphere radius="0.07"/>
      </geometry>
    </collision>
    <collision>
      <origin rpy="-0.291 0 0" xyz="0 0.03 0.1"/>
      <geometry>
        <cylinder length="0.208" radius="0.07"/>
      </geometry>
    </collision>
  </link>
  <!-- Third segment of the arm. Joint along y-axis -->
  <joint name="left_arm_a2_joint" type="revolute">
    <origin rpy="0 0 0" xyz="0 0 0.2005"/>
    <axis xyz="0 -1 0"/>
    <limit effort="176" lower="-2.09439510239" upper="2.09439510239" velocity="1.91986217719"/>
    <dynamics damping="1.0" friction="10.0"/>
    <parent link="left_arm_1_link"/>
    <child link="left_arm_2_link" />
  </joint>
  <joint name="left_arm_a2_joint_stiffness" type="revolute">
    <axis xyz="0 0 1"/>
    <limit effort="0" lower="0" upper="5000" velocity="20000"/>
    <safety_controller k_position="30" k_velocity="30" soft_lower_limit="0" soft_upper_limit="5000"/>
    <parent link="left_arm_1_link" />
    <child link="left_arm_2_link_dummy"/>
  </joint>
  <link name="left_arm_2_link_dummy" />
  <link name="left_arm_2_link">
    <inertial>
      <mass value="2.35" />
      <origin rpy="0 0 0" xyz="0 0.06 0.07"/>
      <inertia ixx="0.0160583333333" ixy="0" ixz="0" iyy="0.003525" iyz="0" izz="0.0139433333333"/>
    </inertial>
    <visual>
      <origin rpy="0 0 3.14159265359" xyz="0 0 0.0" />
      <geometry>
        <mesh filename=""/>
      </geometry>
      <material name="Kuka/Orange"/>
    </visual>
    <collision>
      <origin rpy="0 0 0" xyz="0 0 0.2"/>
      <geometry>
        <sphere radius="0.07"/>
      </geometry>
    </collision>
    <collision>
      <origin rpy="0 0 0" xyz="0 -0.06 0.0"/>
      <geometry>
        <sphere radius="0.07"/>
      </geometry>
    </collision>
    <collision>
      <origin rpy="-0.291 0 0" xyz="0 -0.03 0.1"/>
      <geometry>
        <cylinder length="0.208" radius="0.07"/>
      </geometry>
    </collision>
  </link>
  <!-- Fourth element of the arm. z-axis -->
  <joint name="left_arm_e1_joint" type="revolute">
    <origin rpy="0 0 0" xyz="0 0 0.20"/>
    <axis xyz="0 0 1"/>
    <limit effort="100" lower="-2.96705972839" upper="2.96705972839" velocity="2.23402144255"/>
    <dynamics damping="1.0" friction="10.0" />
    <parent link="left_arm_2_link"/>
    <child link="left_arm_3_link" />
  </joint>
  <joint name="left_arm_e1_joint_stiffness" type="revolute">
    <axis xyz="0 0 1"/>
    <limit effort="0" lower="0" upper="5000" velocity="20000"/>
    <safety_controller k_position="30" k_velocity="30" soft_lower_limit="0" soft_upper_limit="5000"/>
    <parent link="left_arm_2_link" />
    <child link="left_arm_3_link_dummy"/>
  </joint>
  <link name="left_arm_3_link_dummy" />
  <link name="left_arm_3_link">
    <inertial>
      <mass value="2.35" />
      <origin rpy="0 0 0" xyz="0 0.06 0.130"/>
      <inertia ixx="0.0160583333333" ixy="0" ixz="0" iyy="0.003525" iyz="0" izz="0.0139433333333"/>
    </inertial>
    <visual>
      <origin rpy="0 0 3.14159265359" xyz="0 0 -0.008" />
      <geometry>
        <mesh filename=""/>
      </geometry>
      <material name="Kuka/Orange"/>
    </visual>
    <collision>
      <origin rpy="0 0 0" xyz="0 0 0.0"/>
      <geometry>
        <sphere radius="0.07"/>
      </geometry>
    </collision>
    <collision>
      <origin rpy="0 0 0" xyz="0 -0.06 0.2"/>
      <geometry>
        <sphere radius="0.07"/>
      </geometry>
    </collision>
    <collision>
      <origin rpy="0.291 0 0" xyz="0 -0.03 0.1"/>
      <geometry>
        <cylinder length="0.208" radius="0.07"/>
      </geometry>
    </collision>
  </link>
  <!-- fifth element of the arm. x-axis -->
  <joint name="left_arm_a3_joint" type="revolute">
    <origin rpy="0 0 0" xyz="0 0 0.20"/>
    <axis xyz="0 1 0"/>
    <limit effort="100" lower="-2.09439510239" upper="2.09439510239" velocity="2.23402144255"/>
    <dynamics damping="1.0" friction="10.0" />
    <parent link="left_arm_3_link"/>
    <child link="left_arm_4_link" />
  </joint>
  <joint name="left_arm_a3_joint_stiffness" type="revolute">
    <axis xyz="0 0 1"/>
    <limit effort="0" lower="0" upper="5000" velocity="20000"/>
    <safety_controller k_position="30" k_velocity="30" soft_lower_limit="0" soft_upper_limit="5000"/>
    <parent link="left_arm_3_link" />
    <child link="left_arm_4_link_dummy"/>
  </joint>
  <link name="left_arm_4_link_dummy" />
  <link name="left_arm_4_link">
    <inertial>
      <mass value="2.35" />
      <origin rpy="0 0 0" xyz="0 -0.06 0.07"/>
      <inertia ixx="0.0160583333333" ixy="0" ixz="0" iyy="0.003525" iyz="0" izz="0.0139433333333"/>
    </inertial>
    <visual>
      <origin rpy="0 0 3.14159265359" xyz="0 0 0.0" />
      <geometry>
        <mesh filename=""/>
      </geometry>
      <material name="Kuka/Orange"/>
    </visual>
    <collision>
      <origin rpy="0 0 0" xyz="0 0 0.2"/>
      <geometry>
        <sphere radius="0.07"/>
      </geometry>
    </collision>
    <collision>
      <origin rpy="0 0 0" xyz="0 0.06 0.0"/>
      <geometry>
        <sphere radius="0.07"/>
      </geometry>
    </collision>
    <collision>
      <origin rpy="0.291 0 0" xyz="0 0.03 0.1"/>
      <geometry>
        <cylinder length="0.208" radius="0.07"/>
      </geometry>
    </collision>
  </link>
  <!-- Sixth element of the arm. z-axis -->
  <joint name="left_arm_a4_joint" type="revolute">
    <origin rpy="0 0 0" xyz="0 0 0.20"/>
    <axis xyz="0 0 1"/>
    <limit effort="100" lower="-2.96705972839" upper="2.96705972839" velocity="3.56047167407"/>
    <dynamics damping="1.0" friction="10.0" />
    <parent link="left_arm_4_link"/>
    <child link="left_arm_5_link" />
  </joint>
  <joint name="left_arm_a4_joint_stiffness" type="revolute">
    <axis xyz="0 0 1"/>
    <limit effort="0" lower="0" upper="5000" velocity="20000"/>
    <safety_controller k_position="30" k_velocity="30" soft_lower_limit="0" soft_upper_limit="5000"/>
    <parent link="left_arm_4_link" />
    <child link="left_arm_5_link_dummy"/>
  </joint>
  <link name="left_arm_5_link_dummy" />
  <link name="left_arm_5_link">
    <inertial>
      <mass value="2.35" />
      <origin rpy="0 0 0" xyz="0 0 0.124"/>
      <inertia ixx="0.0148645333333" ixy="0" ixz="0" iyy="0.003525" iyz="0" izz="0.0127495333333"/>
    </inertial>
    <visual>
      <origin rpy="0 0 3.14159265359" xyz="0 0 -0.008" />
      <geometry name="left_arm_5_geom">
        <mesh filename=""/>
      </geometry>
      <material name="Kuka/Orange"/>
    </visual>
    <collision>
      <origin rpy="0 0 0" xyz="0 0 0.0"/>
      <geometry>
        <sphere radius="0.07"/>
      </geometry>
    </collision>
    <collision>
      <origin rpy="0 0 0" xyz="0 0.04 0.19"/>
      <geometry>
        <sphere radius="0.07"/>
      </geometry>
    </collision>
    <collision>
      <origin rpy="-0.207 0 0" xyz="0 0.02 0.095"/>
      <geometry>
        <cylinder length="0.198" radius="0.07"/>
      </geometry>
    </collision>
  </link>
  <!-- Seventh element of the arm. z-axis -->
  <joint name="left_arm_a5_joint" type="revolute">
    <origin rpy="0 0 0" xyz="0 0 0.19"/>
    <axis xyz="0 -1 0"/>
    <limit effort="38" lower="-2.09439510239" upper="2.09439510239" velocity="3.21140582367"/>
    <dynamics damping="1.0" friction="10.0" />
    <parent link="left_arm_5_link"/>
    <child link="left_arm_6_link" />
  </joint>
  <joint name="left_arm_a5_joint_stiffness" type="revolute">
    <axis xyz="0 0 1"/>
    <limit effort="0" lower="0" upper="5000" velocity="20000"/>
    <safety_controller k_position="30" k_velocity="30" soft_lower_limit="0" soft_upper_limit="5000"/>
    <parent link="left_arm_5_link" />
    <child link="left_arm_6_link_dummy"/>
  </joint>
  <link name="left_arm_6_link_dummy" />
  <link name="left_arm_6_link">
    <inertial>
      <mass value="1.1" />
      <origin rpy="0 0 0" xyz="0 0 0.0625"/>
      <inertia ixx="0.00286458333333" ixy="0" ixz="0" iyy="0.00286458333333" iyz="0" izz="0.00286458333333" />
    </inertial>
    <visual>
      <origin rpy="0 0 3.14159265359" xyz="0 0 0"/>
      <geometry>
        <mesh filename=""/>
      </geometry>
      <material name="Kuka/Grey"/>
    </visual>
    <collision>
      <origin rpy="0 0 3.14159265359" xyz="0 -0.01 0"/>
      <geometry>
        <sphere radius="0.08"/>
      </geometry>
    </collision>
  </link>
  <!-- Eighth element of the arm. z-axis -->
  <joint name="left_arm_a6_joint" type="revolute">
    <origin rpy="0 0 0" xyz="0 0 0.078"/>
    <axis xyz="0 0 1"/>
    <limit effort="38" lower="-2.96705972839" upper="2.96705972839" velocity="3.21140582367"/>
    <dynamics damping="1.0" friction="10.0" />
    <parent link="left_arm_6_link"/>
    <child link="left_arm_7_link" />
  </joint>
  <joint name="left_arm_a6_joint_stiffness" type="revolute">
    <axis xyz="0 0 1"/>
    <limit effort="0" lower="0" upper="5000" velocity="20000"/>
    <safety_controller k_position="30" k_velocity="30" soft_lower_limit="0" soft_upper_limit="5000"/>
    <parent link="left_arm_6_link" />
    <child link="left_arm_7_link_dummy"/>
  </joint>
  <link name="left_arm_7_link_dummy" />
  <link name="left_arm_7_link">
    <inertial>
      <mass value="0.25" />
      <origin xyz="0 0 0"/>
      <inertia ixx="0.000416666666667" ixy="0" ixz="0" iyy="0.000416666666667" iyz="0" izz="0.000416666666667"/>
    </inertial>
    <visual>
      <origin rpy="0 0 3.14159265359" xyz="0 0 0"/>
      <geometry>
        <mesh filename=""/>
      </geometry>
      <material name="Kuka/DarkGrey"/>
    </visual>
    <collision>
      <origin rpy="0 0 3.14159265359" xyz="0 0 0"/>
      <geometry>
        <cylinder length="0.05" radius="0.04"/>
      </geometry>
    </collision>
  </link>
  <gazebo reference="left_arm_base_link">
    <gravity>true</gravity>
    <material>Gazebo/Orange</material>
  </gazebo>
  <gazebo reference="left_arm_a1_joint">
    <provideFeedback>true</provideFeedback>
  </gazebo>
  <gazebo reference="left_arm_1_link">
    <gravity>true</gravity>
    <material>Gazebo/Orange</material>
  </gazebo>
  <gazebo reference="left_arm_a2_joint">
    <provideFeedback>true</provideFeedback>
  </gazebo>
  <gazebo reference="left_arm_2_link">
    <gravity>true</gravity>
    <material>Gazebo/Orange</material>
  </gazebo>
  <gazebo reference="left_arm_e1_joint">
    <provideFeedback>true</provideFeedback>
  </gazebo>
  <gazebo reference="left_arm_3_link">
    <gravity>true</gravity>
    <material>Gazebo/Orange</material>
  </gazebo>
  <gazebo reference="left_arm_a3_joint">
    <provideFeedback>true</provideFeedback>
  </gazebo>
  <gazebo reference="left_arm_4_link">
    <gravity>true</gravity>
    <material>Gazebo/Orange</material>
  </gazebo>
  <gazebo reference="left_arm_a4_joint">
    <provideFeedback>true</provideFeedback>
  </gazebo>
  <gazebo reference="left_arm_5_link">
    <gravity>true</gravity>
    <material>Gazebo/Orange</material>
  </gazebo>
  <gazebo reference="left_arm_a5_joint">
    <provideFeedback>true</provideFeedback>
  </gazebo>
  <gazebo reference="left_arm_6_link">
    <gravity>true</gravity>
    <material>Gazebo/Orange</material>
  </gazebo>
  <gazebo reference="left_arm_a6_joint">
    <provideFeedback>true</provideFeedback>
  </gazebo>
  <gazebo reference="left_arm_7_link">
    <gravity>true</gravity>
    <material>Gazebo/Grey</material>
  </gazebo>
  <transmission name="left_arm_a1_trans">
    <type>transmission_interface/SimpleTransmission</type>
    <joint name="left_arm_a1_joint">
      <!-- <hardwareInterface>${Interface10}</hardwareInterface> -->
      <hardwareInterface>EffortJointInterface</hardwareInterface>
    </joint>
    <actuator name="left_arm_a1_motor">
      <mechanicalReduction>1</mechanicalReduction>
    </actuator>
  </transmission>
  <transmission name="left_arm_a2_trans">
    <type>transmission_interface/SimpleTransmission</type>
    <joint name="left_arm_a2_joint">
      <!-- <hardwareInterface>${Interface10}</hardwareInterface> -->
      <hardwareInterface>EffortJointInterface</hardwareInterface>
    </joint>
    <actuator name="left_arm_a2_motor">
      <mechanicalReduction>1</mechanicalReduction>
    </actuator>
  </transmission>
  <transmission name="left_arm_e1_trans">
    <type>transmission_interface/SimpleTransmission</type>
    <joint name="left_arm_e1_joint">
      <!-- <hardwareInterface>${Interface10}</hardwareInterface> -->
      <hardwareInterface>EffortJointInterface</hardwareInterface>
    </joint>
    <actuator name="left_arm_e1_motor">
      <mechanicalReduction>1</mechanicalReduction>
    </actuator>
  </transmission>
  <transmission name="left_arm_a3_trans">
    <type>transmission_interface/SimpleTransmission</type>
    <joint name="left_arm_a3_joint">
      <!-- <hardwareInterface>${Interface10}</hardwareInterface> -->
      <hardwareInterface>EffortJointInterface</hardwareInterface>
    </joint>
    <actuator name="left_arm_a3_motor">
      <mechanicalReduction>1</mechanicalReduction>
    </actuator>
  </transmission>
  <transmission name="left_arm_a4_trans">
    <type>transmission_interface/SimpleTransmission</type>
    <joint name="left_arm_a4_joint">
      <!-- <hardwareInterface>${Interface10}</hardwareInterface> -->
      <hardwareInterface>EffortJointInterface</hardwareInterface>
    </joint>
    <actuator name="left_arm_a4_motor">
      <mechanicalReduction>1</mechanicalReduction>
    </actuator>
  </transmission>
  <transmission name="left_arm_a5_trans">
    <type>transmission_interface/SimpleTransmission</type>
    <joint name="left_arm_a5_joint">
      <!-- <hardwareInterface>${Interface10}</hardwareInterface> -->
      <hardwareInterface>EffortJointInterface</hardwareInterface>
    </joint>
    <actuator name="left_arm_a5_motor">
      <mechanicalReduction>1</mechanicalReduction>
    </actuator>
  </transmission>
  <transmission name="left_arm_a6_trans">
    <type>transmission_interface/SimpleTransmission</type>
    <joint name="left_arm_a6_joint">
      <!-- <hardwareInterface>${Interface10}</hardwareInterface> -->
      <hardwareInterface>EffortJointInterface</hardwareInterface>
    </joint>
    <actuator name="left_arm_a6_motor">
      <mechanicalReduction>1</mechanicalReduction>
    </actuator>
  </transmission>
  <!-- joint between arm_7_link and sdh_palm_link -->
  <joint name="left_hand_palm_joint" type="fixed">
    <origin rpy="0 0 0" xyz="0 0 0"/>
    <parent link="left_arm_7_link"/>
    <child link="left_hand_palm_link"/>
  </joint>
  <link name="left_hand_palm_link">
    <inertial>
      <origin rpy="0 0 0" xyz="0 0 0"/>
      <mass value="1"/>
      <inertia ixx="0.01" ixy="0" ixz="0" iyy="0.01" iyz="0" izz="0.01"/>
    </inertial>
    <visual>
      <origin rpy="0 0 0" xyz="0 0 0" />
      <geometry>
        <mesh filename=""/>
      </geometry>
      <material name="Schunk/LightGrey"/>
    </visual>
    <collision>
      <origin rpy="0 0 0" xyz="0 0 0"/>
      <geometry>
        <mesh filename=""/>
      </geometry>
    </collision>
  </link>
  <!-- grasp link -->
  <joint name="left_hand_grasp_joint" type="fixed">
    <origin rpy="0 0 0" xyz="0 0 0.15" />
    <parent link="left_hand_palm_link"/>
    <child link="left_hand_grasp_link" />
  </joint>
  <link name="left_hand_grasp_link"/>
  <!-- tip link -->
  <joint name="left_hand_tip_joint" type="fixed">
    <origin rpy="0 0 0" xyz="0 0 0.22"/>
    <parent link="left_hand_palm_link"/>
    <child link="left_hand_tip_link"/>
  </joint>
  <link name="left_hand_tip_link"/>
  <!-- finger1 -->
  <!-- joint between sdh_palm_link and sdh_finger_11_link -->
  <joint name="left_hand_knuckle_joint" type="revolute">
    <origin rpy="0 0 3.14159265" xyz="0.01905 0.033 0.0745"/>
    <parent link="left_hand_palm_link" />
    <child link="left_hand_finger_11_link"/>
    <axis xyz="0 0 1"/>
    <dynamics damping="0.7" friction="0"/>
    <limit effort="100" lower="0" upper="1.570796327" velocity="0.5"/>
  </joint>
  <link name="left_hand_finger_11_link">
    <inertial>
      <origin rpy="0 0 0" xyz="0 0 0"/>
      <mass value="0.1"/>
      <inertia ixx="0.01" ixy="0" ixz="0" iyy="0.01" iyz="0" izz="0.01"/>
    </inertial>
    <visual>
      <origin rpy="0 0 0" xyz="0 0 0"/>
      <geometry>
        <mesh filename=""/>
      </geometry>
      <material name="Schunk/LightGrey"/>
    </visual>
    <collision>
      <origin rpy="0 0 0" xyz="0 0 0"/>
      <geometry>
        <mesh filename=""/>
      </geometry>
    </collision>
  </link>
  <!-- joint between sdh_finger_11_link and sdh_finger_12_link -->
  <joint name="left_hand_finger_12_joint" type="revolute">
    <origin rpy="0 0 0" xyz="0 0 0.0165"/>
    <parent link="left_hand_finger_11_link"/>
    <child link="left_hand_finger_12_link"/>
    <axis xyz="0 1 0"/>
    <dynamics damping="0.7" friction="0"/>
    <limit effort="100" lower="-1.570796327" upper="1.570796327" velocity="0.5"/>
  </joint>
  <link name="left_hand_finger_12_link">
    <inertial>
      <origin rpy="0 0 0" xyz="0 0 0"/>
      <mass value="0.1"/>
      <inertia ixx="0.01" ixy="0" ixz="0" iyy="0.01" iyz="0" izz="0.01"/>
    </inertial>
    <visual>
      <origin rpy="0 0 0" xyz="0 0 0"/>
      <geometry>
        <mesh filename=""/>
      </geometry>
      <material name="Schunk/LightGrey"/>
    </visual>
    <collision>
      <origin rpy="0 0 0" xyz="0 0 0"/>
      <geometry>
        <mesh filename=""/>
      </geometry>
    </collision>
  </link>
  <!-- joint between sdh_finger_12_link and sdh_finger_13_link -->
  <joint name="left_hand_finger_13_joint" type="revolute">
    <origin rpy="0 0 0" xyz="0 0 0.0865"/>
    <parent link="left_hand_finger_12_link"/>
    <child link="left_hand_finger_13_link"/>
    <axis xyz="0 1 0"/>
    <dynamics damping="0.7" friction="0"/>
    <limit effort="100" lower="-1.570796327" upper="1.570796327" velocity="0.5"/>
  </joint>
  <link name="left_hand_finger_13_link">
    <inertial>
      <origin rpy="0 0 0" xyz="0 0 0"/>
      <mass value="0.1"/>
      <inertia ixx="0.01" ixy="0" ixz="0" iyy="0.01" iyz="0" izz="0.01"/>
    </inertial>
    <visual>
      <origin rpy="0 0 0" xyz="0 0 0"/>
      <geometry>
        <mesh filename=""/>
      </geometry>
      <material name="Schunk/LightGrey"/>
    </visual>
    <collision>
      <origin rpy="0 0 0" xyz="0 0 0"/>
      <geometry>
        <mesh filename=""/>
      </geometry>
    </collision>
  </link>
  <!-- finger2 -->
  <!-- joint between sdh_palm_link and sdh_finger_21_link -->
  <joint name="left_hand_finger_21_joint" type="revolute">
    <mimic joint="left_hand_knuckle_joint" multiplier="1" offset="0"/>
    <origin rpy="0 0 3.14159265" xyz="0.01905 -0.033 0.0745" />
    <parent link="left_hand_palm_link"/>
    <child link="left_hand_finger_21_link" />
    <axis xyz="0 0 -1"/>
    <dynamics damping="0.7" friction="0"/>
    <limit effort="100" lower="0" upper="1.570796327" velocity="0.5"/>
  </joint>
  <link name="left_hand_finger_21_link">
    <inertial>
      <origin rpy="0 0 0" xyz="0 0 0"/>
      <mass value="0.1"/>
      <inertia ixx="0.01" ixy="0" ixz="0" iyy="0.01" iyz="0" izz="0.01"/>
    </inertial>
    <visual>
      <origin rpy="0 0 0" xyz="0 0 0"/>
      <geometry>
        <mesh filename=""/>
      </geometry>
      <material name="Schunk/LightGrey"/>
    </visual>
    <collision>
      <origin rpy="0 0 0" xyz="0 0 0"/>
      <geometry>
        <mesh filename=""/>
      </geometry>
    </collision>
  </link>
  <!-- joint between sdh_finger_21_link and sdh_finger_22_link -->
  <joint name="left_hand_finger_22_joint" type="revolute">
    <origin rpy="0 0 0" xyz="0 0 0.0165"/>
    <parent link="left_hand_finger_21_link"/>
    <child link="left_hand_finger_22_link"/>
    <axis xyz="0 1 0"/>
    <dynamics damping="0.7" friction="0"/>
    <limit effort="100" lower="-1.570796327" upper="1.570796327" velocity="0.5"/>
  </joint>
  <link name="left_hand_finger_22_link">
    <inertial>
      <origin rpy="0 0 0" xyz="0 0 0"/>
      <mass value="0.1"/>
      <inertia ixx="0.01" ixy="0" ixz="0" iyy="0.01" iyz="0" izz="0.01"/>
    </inertial>
    <visual>
      <origin rpy="0 0 0" xyz="0 0 0"/>
      <geometry>
        <mesh filename=""/>
      </geometry>
      <material name="Schunk/LightGrey"/>
    </visual>
    <collision>
      <origin rpy="0 0 0" xyz="0 0 0"/>
      <geometry>
        <mesh filename=""/>
      </geometry>
    </collision>
  </link>
  <!-- joint between sdh_finger_22_link and sdh_finger_23_link -->
  <joint name="left_hand_finger_23_joint" type="revolute">
    <origin rpy="0 0 0" xyz="0 0 0.0865"/>
    <parent link="left_hand_finger_22_link"/>
    <child link="left_hand_finger_23_link"/>
    <axis xyz="0 1 0"/>
    <dynamics damping="0.7" friction="0"/>
    <limit effort="100" lower="-1.570796327" upper="1.570796327" velocity="0.5"/>
  </joint>
  <link name="left_hand_finger_23_link">
    <inertial>
      <origin rpy="0 0 0" xyz="0 0 0"/>
      <mass value="0.1"/>
      <inertia ixx="0.01" ixy="0" ixz="0" iyy="0.01" iyz="0" izz="0.01"/>
    </inertial>
    <visual>
      <origin rpy="0 0 0" xyz="0 0 0"/>
      <geometry>
        <mesh filename=""/>
      </geometry>
      <material name="Schunk/LightGrey"/>
    </visual>
    <collision>
      <origin rpy="0 0 0" xyz="0 0 0"/>
      <geometry>
        <mesh filename=""/>
      </geometry>
    </collision>
  </link>
  <!-- thumb -->
  <!-- joint between sdh_palm_link and sdh_thumb_1_link -->
  <joint name="left_hand_thumb_1_joint" type="fixed">
    <origin rpy="0 0 0" xyz="-0.03811 0 0.0745 "/>
    <parent link="left_hand_palm_link"/>
    <child link="left_hand_thumb_1_link"/>
  </joint>
  <link name="left_hand_thumb_1_link">
    <inertial>
      <origin rpy="0 0 0" xyz="0 0 0"/>
      <mass value="0.1"/>
      <inertia ixx="0.01" ixy="0" ixz="0" iyy="0.01" iyz="0" izz="0.01"/>
    </inertial>
    <visual>
      <origin rpy="0 0 0" xyz="0 0 0"/>
      <geometry>
        <mesh filename=""/>
      </geometry>
      <material name="Schunk/LightGrey"/>
    </visual>
    <collision>
      <origin rpy="0 0 0" xyz="0 0 0"/>
      <geometry>
        <mesh filename=""/>
      </geometry>
    </collision>
  </link>
  <!-- joint between sdh_thumb_1_link and shd_thumb_2_link -->
  <joint name="left_hand_thumb_2_joint" type="revolute">
    <origin rpy="0 0 0" xyz="0 0 0.0165"/>
    <parent link="left_hand_thumb_1_link" />
    <child link="left_hand_thumb_2_link"/>
    <axis xyz="0 1 0"/>
    <dynamics damping="0.7" friction="0"/>
    <limit effort="100" lower="-1.570796327" upper="1.570796327" velocity="0.5"/>
  </joint>
  <link name="left_hand_thumb_2_link">
    <inertial>
      <origin rpy="0 0 0" xyz="0 0 0"/>
      <mass value="0.1"/>
      <inertia ixx="0.01" ixy="0" ixz="0" iyy="0.01" iyz="0" izz="0.01"/>
    </inertial>
    <visual>
      <origin rpy="0 0 0" xyz="0 0 0"/>
      <geometry>
        <mesh filename=""/>
      </geometry>
      <material name="Schunk/LightGrey"/>
    </visual>
    <collision>
      <origin rpy="0 0 0" xyz="0 0 0"/>
      <geometry>
        <mesh filename=""/>
      </geometry>
    </collision>
  </link>
  <!-- joint between sdh_thumb_2_link and sdh_thumb_3_link -->
  <joint name="left_hand_thumb_3_joint" type="revolute">
    <origin rpy="0 0 0" xyz="0 0 0.0865"/>
    <parent link="left_hand_thumb_2_link" />
    <child link="left_hand_thumb_3_link"/>
    <axis xyz="0 1 0"/>
    <dynamics damping="0.7" friction="0"/>
    <limit effort="100" lower="-1.570796327" upper="1.570796327" velocity="0.5"/>
  </joint>
  <link name="left_hand_thumb_3_link">
    <inertial>
      <origin rpy="0 0 0" xyz="0 0 0"/>
      <mass value="0.1"/>
      <inertia ixx="0.01" ixy="0" ixz="0" iyy="0.01" iyz="0" izz="0.01"/>
    </inertial>
    <visual>
      <origin rpy="0 0 0" xyz="0 0 0"/>
      <geometry>
        <mesh filename=""/>
      </geometry>
      <material name="Schunk/LightGrey"/>
    </visual>
    <collision>
      <origin rpy="0 0 0" xyz="0 0 0"/>
      <geometry>
        <mesh filename=""/>
      </geometry>
    </collision>
  </link>
  <gazebo reference="left_hand_palm_link">
    <material>Schunk/LightGrey</material>
    <turnGravityOff>false</turnGravityOff>
  </gazebo>
  <gazebo reference="left_hand_finger_11_link">
    <material>Schunk/LightGrey</material>
    <turnGravityOff>false</turnGravityOff>
    <mu1>1000</mu1>
    <mu2>1000</mu2>
    <kp>1e5</kp>
    <kd>1.0</kd>
  </gazebo>
  <gazebo reference="left_hand_finger_12_link">
    <selfCollide>true</selfCollide>
    <sensor name="left_hand_finger_12_contact_sensor" type="contact">
      <always_on>true</always_on>
      <update_rate>100</update_rate>
      <contact>
        <collision>left_hand_finger_12_link_geom</collision>
      </contact>

    </sensor>
    <material>Schunk/LightGrey</material>
    <turnGravityOff>false</turnGravityOff>
    <mu1>1000</mu1>
    <mu2>1000</mu2>
    <kp>1e5</kp>
    <kd>1.0</kd>
  </gazebo>
  <gazebo reference="left_hand_finger_13_link">
    <selfCollide>true</selfCollide>
    <sensor name="left_hand_finger_13_contact_sensor" type="contact">
      <always_on>true</always_on>
      <update_rate>100</update_rate>
      <contact>
        <collision>left_hand_finger_13_link_geom</collision>
      </contact>
    </sensor>
    <material>Schunk/LightGrey</material>
    <mu1>1000</mu1>
    <mu2>1000</mu2>
    <kp>1e5</kp>
    <kd>1.0</kd>
  </gazebo>
  <gazebo reference="left_hand_finger_21_link">
    <material>Schunk/LightGrey</material>
    <turnGravityOff>false</turnGravityOff>
    <mu1>1000</mu1>
    <mu2>1000</mu2>
    <kp>1e5</kp>
    <kd>1.0</kd>
  </gazebo>
  <gazebo reference="left_hand_finger_22_link">
    <selfCollide>true</selfCollide>
    <sensor name="left_hand_finger_22_contact_sensor" type="contact">
      <always_on>true</always_on>
      <update_rate>100</update_rate>
      <contact>
        <collision>left_hand_finger_22_link_geom</collision>
      </contact>

    </sensor>
    <material>Schunk/LightGrey</material>
    <turnGravityOff>false</turnGravityOff>
    <mu1>1000</mu1>
    <mu2>1000</mu2>
    <kp>1e5</kp>
    <kd>1.0</kd>
  </gazebo>
  <gazebo reference="left_hand_finger_23_link">
    <selfCollide>true</selfCollide>
    <sensor name="left_hand_finger_23_contact_sensor" type="contact">
      <always_on>true</always_on>
      <update_rate>100</update_rate>
      <contact>
        <collision>left_hand_finger_23_link_geom</collision>
      </contact>

    </sensor>
    <material>Schunk/LightGrey</material>
    <mu1>1000</mu1>
    <mu2>1000</mu2>
    <kp>1e5</kp>
    <kd>1.0</kd>
  </gazebo>
  <gazebo reference="left_hand_thumb_1_link">
    <material>Schunk/LightGrey</material>
    <turnGravityOff>false</turnGravityOff>
    <mu1>1000</mu1>
    <mu2>1000</mu2>
    <kp>1e5</kp>
    <kd>1.0</kd>
  </gazebo>
  <gazebo reference="left_hand_thumb_2_link">
    <selfCollide>true</selfCollide>
    <sensor name="left_hand_thumb_2_contact_sensor" type="contact">
      <always_on>true</always_on>
      <update_rate>100</update_rate>
      <contact>
        <collision>left_hand_thumb_2_link_geom</collision>
      </contact>

    </sensor>
    <material>Schunk/LightGrey</material>
    <turnGravityOff>false</turnGravityOff>
    <mu1>1000</mu1>
    <mu2>1000</mu2>
    <kp>1e5</kp>
    <kd>1.0</kd>
  </gazebo>
  <gazebo reference="left_hand_thumb_3_link">
    <selfCollide>true</selfCollide>
    <sensor name="left_hand_thumb_3_contact_sensor" type="contact">
      <always_on>true</always_on>
      <update_rate>100</update_rate>
      <contact>
        <collision>left_hand_thumb_3_link_geom</collision>
      </contact>

    </sensor>
    <material>Schunk/LightGrey</material>
    <mu1>1000</mu1>
    <mu2>1000</mu2>
    <kp>1e5</kp>
    <kd>1.0</kd>
  </gazebo>
  <gazebo reference="left_hand_knuckle_joint">
    <implicitSpringDamper>1</implicitSpringDamper>
  </gazebo>
  <gazebo reference="left_hand_finger_12_joint">
    <implicitSpringDamper>1</implicitSpringDamper>
  </gazebo>
  <gazebo reference="left_hand_finger_13_joint">
    <implicitSpringDamper>1</implicitSpringDamper>
  </gazebo>
  <gazebo reference="left_hand_finger_21_joint">
    <implicitSpringDamper>1</implicitSpringDamper>
  </gazebo>
  <gazebo reference="left_hand_finger_22_joint">
    <implicitSpringDamper>1</implicitSpringDamper>
  </gazebo>
  <gazebo reference="left_hand_finger_23_joint">
    <implicitSpringDamper>1</implicitSpringDamper>
  </gazebo>
  <gazebo reference="left_hand_thumb_1_joint">
    <implicitSpringDamper>1</implicitSpringDamper>
  </gazebo>
  <gazebo reference="left_hand_thumb_2_joint">
    <implicitSpringDamper>1</implicitSpringDamper>
  </gazebo>
  <gazebo reference="left_hand_thumb_3_joint">
    <implicitSpringDamper>1</implicitSpringDamper>
  </gazebo>
  <!-- <transmission name="${name}_finger_21_trans">
      <type>transmission_interface/SimpleTransmission</type>
  			<joint name="${name}_finger_21_joint">
        <hardwareInterface>PositionJointInterface</hardwareInterface>
      </joint>
		  <actuator name="${name}_finger_21_motor">
			  <mechanicalReduction>1</mechanicalReduction>
      </actuator>
		</transmission> -->
  <transmission name="left_hand_knuckle_trans">
    <type>transmission_interface/SimpleTransmission</type>
    <joint name="left_hand_knuckle_joint">
      <hardwareInterface>EffortJointInterface</hardwareInterface>
    </joint>
    <actuator name="left_hand_knuckle_motor">
      <hardwareInterface>EffortJointInterface</hardwareInterface>
      <mechanicalReduction>1</mechanicalReduction>
    </actuator>
  </transmission>
  <!-- finger1 -->
  <transmission name="left_hand_finger_12_trans">
    <type>transmission_interface/SimpleTransmission</type>
    <joint name="left_hand_finger_12_joint">
      <hardwareInterface>EffortJointInterface</hardwareInterface>
    </joint>
    <actuator name="left_hand_finger_12_motor">
      <hardwareInterface>EffortJointInterface</hardwareInterface>
      <mechanicalReduction>1</mechanicalReduction>
    </actuator>
  </transmission>
  <transmission name="left_hand_finger_13_trans">
    <type>transmission_interface/SimpleTransmission</type>
    <joint name="left_hand_finger_13_joint">
      <hardwareInterface>EffortJointInterface</hardwareInterface>
    </joint>
    <actuator name="left_hand_finger_13_motor">
      <hardwareInterface>EffortJointInterface</hardwareInterface>
      <mechanicalReduction>1</mechanicalReduction>
    </actuator>
  </transmission>
  <!-- finger2 -->
  <transmission name="left_hand_finger_22_trans" type="pr2_mechfinger_21anism_model/SimpleTransmission">
    <type>transmission_interface/SimpleTransmission</type>
    finger_21
			
    <joint name="left_hand_finger_22_joint">
      <hardwareInterface>EffortJointInterface</hardwareInterface>
    </joint>
    <actuator name="left_hand_finger_22_motor">
      <hardwareInterface>EffortJointInterface</hardwareInterface>
      <mechanicalReduction>1</mechanicalReduction>
    </actuator>
  </transmission>
  <transmission name="left_hand_finger_23_trans">
    <type>transmission_interface/SimpleTransmission</type>
    <joint name="left_hand_finger_23_joint">
      <hardwareInterface>EffortJointInterface</hardwareInterface>
    </joint>
    <actuator name="left_hand_finger_23_motor">
      <hardwareInterface>EffortJointInterface</hardwareInterface>
      <mechanicalReduction>1</mechanicalReduction>
    </actuator>
  </transmission>
  <!-- thumb -->
  <transmission name="left_hand_thumb_2_trans">
    <type>transmission_interface/SimpleTransmission</type>
    <joint name="left_hand_thumb_2_joint">
      <hardwareInterface>EffortJointInterface</hardwareInterface>
    </joint>
    <actuator name="left_hand_thumb_2_motor">
      <hardwareInterface>EffortJointInterface</hardwareInterface>
      <mechanicalReduction>1</mechanicalReduction>
    </actuator>
  </transmission>
  <transmission name="left_hand_thumb_3_trans">
    <type>transmission_interface/SimpleTransmission</type>
    <joint name="left_hand_thumb_3_joint">
      <hardwareInterface>EffortJointInterface</hardwareInterface>
    </joint>
    <actuator name="left_hand_thumb_3_motor">
      <hardwareInterface>EffortJointInterface</hardwareInterface>
      <mechanicalReduction>1</mechanicalReduction>
    </actuator>
  </transmission>
  <joint name="right_arm_base_plate_joint" type="fixed">
    <origin rpy="0 0 0" xyz="-0.130 -0.353 0.007525"/>
    <parent link="base_link"/>
    <child link="right_arm_base_plate_link"/>
  </joint>
  <link name="right_arm_base_plate_link">
    <inertial>
      <origin xyz="0 0 0"/>
      <mass value="2.0"/>
      <inertia ixx="0.02" ixy="0.0" ixz="0.0" iyy="0.02" iyz="0.0" izz="0.02"/>
    </inertial>
    <visual>
      <geometry>
        <box size="0.275 0.275 0.0155"/>
      </geometry>
      <material name="LightGrey"/>
    </visual>
    <collision>
      <geometry>
        <box size="0.275 0.275 0.0155"/>
      </geometry>
    </collision>
  </link>
  <gazebo reference="right_arm_base_plate_link">
    <!-- <selfCollide>true</selfCollide> -->
    <material>Gazebo/Grey</material>
  </gazebo>
  <!-- First (shoulder) element of the arm. Fixed to its parent. -->
  <joint name="base_link_right_arm_base_joint" type="fixed">
    <origin rpy="0 0 3.14159265359" xyz="-0.130 -0.353 0.0155" />
    <!-- <origin rpy="0 0 0" xyz="0 0 0"/> -->
    <parent link="base_link"/>
    <child link="calib_right_arm_base_link"/>
  </joint>
  <!-- In the original setting the arm was rotated around 180 degrees around the z axis because the point at the arm base, where the cables are located should point to the direction of the positive x axis of the arm reference frame. This link is used to correct that -->
  <link name="calib_right_arm_base_link"/>
  <!-- Rotate arm around 180 degrees along z axis -->
  <joint name="calib_right_arm_base_joint" type="fixed">
    <!-- cahnges <origin xyz="0 0 0" rpy="0 0 ${M_PI}" /> -->
    <origin rpy="0 0 0" xyz="0 0 0"/>
    <parent link="calib_right_arm_base_link" />
    <child link="right_arm_base_link"/>
  </joint>
  <link name="right_arm_base_link">
    <inertial>
      <mass value="2.0"/>
      <origin xyz="0 0 0.055" />
      <inertia ixx="0.00381666666667" ixy="0" ixz="0" iyy="0.0036" iyz="0" izz="0.00381666666667"/>
    </inertial>
    <visual>
      <origin rpy="0 0 3.14159265359" xyz="0 0 0"/>
      <geometry>
        <mesh filename=""/>
      </geometry>
      <material name="Kuka/Orange"/>
    </visual>
    <collision>
      <origin rpy="0 0 3.14159265359" xyz="0 0 0.055"/>
      <geometry>
        <cylinder length="0.11" radius="0.07"/>
      </geometry>
    </collision>
  </link>
  <!-- Second segment of the arm. Joint along z-axis -->
  <joint name="right_arm_a1_joint" type="revolute">
    <origin rpy="0 0 0" xyz="0 0 0.11"/>
    <axis xyz="0 0 1"/>
    <limit effort="176" lower="-2.96705972839" upper="2.96705972839" velocity="1.91986217719"/>
    <dynamics damping="1.0" friction="10.0" />
    <parent link="right_arm_base_link"/>
    <child link="right_arm_1_link" />
  </joint>
  <joint name="right_arm_a1_joint_stiffness" type="revolute">
    <axis xyz="0 0 1"/>
    <limit effort="0" lower="0" upper="5000" velocity="20000"/>
    <safety_controller k_position="30" k_velocity="30" soft_lower_limit="0" soft_upper_limit="5000"/>
    <parent link="right_arm_base_link" />
    <child link="right_arm_1_link_dummy"/>
  </joint>
  <link name="right_arm_1_link_dummy" />
  <link name="right_arm_1_link">
    <inertial>
      <mass value="2.35" />
      <origin rpy="0 0 0" xyz="0 -0.06 0.130"/>
      <inertia ixx="0.0160583333333" ixy="0" ixz="0" iyy="0.003525" iyz="0" izz="0.0139433333333"/>
    </inertial>
    <visual>
      <origin rpy="0 0 3.14159265359" xyz="0 0 -0.008" />
      <geometry>
        <mesh filename=""/>
      </geometry>
      <material name="Kuka/Orange"/>
    </visual>
    <collision>
      <origin rpy="0 0 0" xyz="0 0 0.0"/>
      <geometry>
        <sphere radius="0.07"/>
      </geometry>
    </collision>
    <collision>
      <origin rpy="0 0 0" xyz="0 0.06 0.2"/>
      <geometry>
        <sphere radius="0.07"/>
      </geometry>
    </collision>
    <collision>
      <origin rpy="-0.291 0 0" xyz="0 0.03 0.1"/>
      <geometry>
        <cylinder length="0.208" radius="0.07"/>
      </geometry>
    </collision>
  </link>
  <!-- Third segment of the arm. Joint along y-axis -->
  <joint name="right_arm_a2_joint" type="revolute">
    <origin rpy="0 0 0" xyz="0 0 0.2005"/>
    <axis xyz="0 -1 0"/>
    <limit effort="176" lower="-2.09439510239" upper="2.09439510239" velocity="1.91986217719"/>
    <dynamics damping="1.0" friction="10.0"/>
    <parent link="right_arm_1_link"/>
    <child link="right_arm_2_link" />
  </joint>
  <joint name="right_arm_a2_joint_stiffness" type="revolute">
    <axis xyz="0 0 1"/>
    <limit effort="0" lower="0" upper="5000" velocity="20000"/>
    <safety_controller k_position="30" k_velocity="30" soft_lower_limit="0" soft_upper_limit="5000"/>
    <parent link="right_arm_1_link" />
    <child link="right_arm_2_link_dummy"/>
  </joint>
  <link name="right_arm_2_link_dummy" />
  <link name="right_arm_2_link">
    <inertial>
      <mass value="2.35" />
      <origin rpy="0 0 0" xyz="0 0.06 0.07"/>
      <inertia ixx="0.0160583333333" ixy="0" ixz="0" iyy="0.003525" iyz="0" izz="0.0139433333333"/>
    </inertial>
    <visual>
      <origin rpy="0 0 3.14159265359" xyz="0 0 0.0" />
      <geometry>
        <mesh filename=""/>
      </geometry>
      <material name="Kuka/Orange"/>
    </visual>
    <collision>
      <origin rpy="0 0 0" xyz="0 0 0.2"/>
      <geometry>
        <sphere radius="0.07"/>
      </geometry>
    </collision>
    <collision>
      <origin rpy="0 0 0" xyz="0 -0.06 0.0"/>
      <geometry>
        <sphere radius="0.07"/>
      </geometry>
    </collision>
    <collision>
      <origin rpy="-0.291 0 0" xyz="0 -0.03 0.1"/>
      <geometry>
        <cylinder length="0.208" radius="0.07"/>
      </geometry>
    </collision>
  </link>
  <!-- Fourth element of the arm. z-axis -->
  <joint name="right_arm_e1_joint" type="revolute">
    <origin rpy="0 0 0" xyz="0 0 0.20"/>
    <axis xyz="0 0 1"/>
    <limit effort="100" lower="-2.96705972839" upper="2.96705972839" velocity="2.23402144255"/>
    <dynamics damping="1.0" friction="10.0" />
    <parent link="right_arm_2_link"/>
    <child link="right_arm_3_link" />
  </joint>
  <joint name="right_arm_e1_joint_stiffness" type="revolute">
    <axis xyz="0 0 1"/>
    <limit effort="0" lower="0" upper="5000" velocity="20000"/>
    <safety_controller k_position="30" k_velocity="30" soft_lower_limit="0" soft_upper_limit="5000"/>
    <parent link="right_arm_2_link" />
    <child link="right_arm_3_link_dummy"/>
  </joint>
  <link name="right_arm_3_link_dummy" />
  <link name="right_arm_3_link">
    <inertial>
      <mass value="2.35" />
      <origin rpy="0 0 0" xyz="0 0.06 0.130"/>
      <inertia ixx="0.0160583333333" ixy="0" ixz="0" iyy="0.003525" iyz="0" izz="0.0139433333333"/>
    </inertial>
    <visual>
      <origin rpy="0 0 3.14159265359" xyz="0 0 -0.008" />
      <geometry>
        <mesh filename=""/>
      </geometry>
      <material name="Kuka/Orange"/>
    </visual>
    <collision>
      <origin rpy="0 0 0" xyz="0 0 0.0"/>
      <geometry>
        <sphere radius="0.07"/>
      </geometry>
    </collision>
    <collision>
      <origin rpy="0 0 0" xyz="0 -0.06 0.2"/>
      <geometry>
        <sphere radius="0.07"/>
      </geometry>
    </collision>
    <collision>
      <origin rpy="0.291 0 0" xyz="0 -0.03 0.1"/>
      <geometry>
        <cylinder length="0.208" radius="0.07"/>
      </geometry>
    </collision>
  </link>
  <!-- fifth element of the arm. x-axis -->
  <joint name="right_arm_a3_joint" type="revolute">
    <origin rpy="0 0 0" xyz="0 0 0.20"/>
    <axis xyz="0 1 0"/>
    <limit effort="100" lower="-2.09439510239" upper="2.09439510239" velocity="2.23402144255"/>
    <dynamics damping="1.0" friction="10.0" />
    <parent link="right_arm_3_link"/>
    <child link="right_arm_4_link" />
  </joint>
  <joint name="right_arm_a3_joint_stiffness" type="revolute">
    <axis xyz="0 0 1"/>
    <limit effort="0" lower="0" upper="5000" velocity="20000"/>
    <safety_controller k_position="30" k_velocity="30" soft_lower_limit="0" soft_upper_limit="5000"/>
    <parent link="right_arm_3_link" />
    <child link="right_arm_4_link_dummy"/>
  </joint>
  <link name="right_arm_4_link_dummy" />
  <link name="right_arm_4_link">
    <inertial>
      <mass value="2.35" />
      <origin rpy="0 0 0" xyz="0 -0.06 0.07"/>
      <inertia ixx="0.0160583333333" ixy="0" ixz="0" iyy="0.003525" iyz="0" izz="0.0139433333333"/>
    </inertial>
    <visual>
      <origin rpy="0 0 3.14159265359" xyz="0 0 0.0" />
      <geometry>
        <mesh filename=""/>
      </geometry>
      <material name="Kuka/Orange"/>
    </visual>
    <collision>
      <origin rpy="0 0 0" xyz="0 0 0.2"/>
      <geometry>
        <sphere radius="0.07"/>
      </geometry>
    </collision>
    <collision>
      <origin rpy="0 0 0" xyz="0 0.06 0.0"/>
      <geometry>
        <sphere radius="0.07"/>
      </geometry>
    </collision>
    <collision>
      <origin rpy="0.291 0 0" xyz="0 0.03 0.1"/>
      <geometry>
        <cylinder length="0.208" radius="0.07"/>
      </geometry>
    </collision>
  </link>
  <!-- Sixth element of the arm. z-axis -->
  <joint name="right_arm_a4_joint" type="revolute">
    <origin rpy="0 0 0" xyz="0 0 0.20"/>
    <axis xyz="0 0 1"/>
    <limit effort="100" lower="-2.96705972839" upper="2.96705972839" velocity="3.56047167407"/>
    <dynamics damping="1.0" friction="10.0" />
    <parent link="right_arm_4_link"/>
    <child link="right_arm_5_link" />
  </joint>
  <joint name="right_arm_a4_joint_stiffness" type="revolute">
    <axis xyz="0 0 1"/>
    <limit effort="0" lower="0" upper="5000" velocity="20000"/>
    <safety_controller k_position="30" k_velocity="30" soft_lower_limit="0" soft_upper_limit="5000"/>
    <parent link="right_arm_4_link" />
    <child link="right_arm_5_link_dummy"/>
  </joint>
  <link name="right_arm_5_link_dummy" />
  <link name="right_arm_5_link">
    <inertial>
      <mass value="2.35" />
      <origin rpy="0 0 0" xyz="0 0 0.124"/>
      <inertia ixx="0.0148645333333" ixy="0" ixz="0" iyy="0.003525" iyz="0" izz="0.0127495333333"/>
    </inertial>
    <visual>
      <origin rpy="0 0 3.14159265359" xyz="0 0 -0.008" />
      <geometry name="right_arm_5_geom">
        <mesh filename=""/>
      </geometry>
      <material name="Kuka/Orange"/>
    </visual>
    <collision>
      <origin rpy="0 0 0" xyz="0 0 0.0"/>
      <geometry>
        <sphere radius="0.07"/>
      </geometry>
    </collision>
    <collision>
      <origin rpy="0 0 0" xyz="0 0.04 0.19"/>
      <geometry>
        <sphere radius="0.07"/>
      </geometry>
    </collision>
    <collision>
      <origin rpy="-0.207 0 0" xyz="0 0.02 0.095"/>
      <geometry>
        <cylinder length="0.198" radius="0.07"/>
      </geometry>
    </collision>
  </link>
  <!-- Seventh element of the arm. z-axis -->
  <joint name="right_arm_a5_joint" type="revolute">
    <origin rpy="0 0 0" xyz="0 0 0.19"/>
    <axis xyz="0 -1 0"/>
    <limit effort="38" lower="-2.09439510239" upper="2.09439510239" velocity="3.21140582367"/>
    <dynamics damping="1.0" friction="10.0" />
    <parent link="right_arm_5_link"/>
    <child link="right_arm_6_link" />
  </joint>
  <joint name="right_arm_a5_joint_stiffness" type="revolute">
    <axis xyz="0 0 1"/>
    <limit effort="0" lower="0" upper="5000" velocity="20000"/>
    <safety_controller k_position="30" k_velocity="30" soft_lower_limit="0" soft_upper_limit="5000"/>
    <parent link="right_arm_5_link" />
    <child link="right_arm_6_link_dummy"/>
  </joint>
  <link name="right_arm_6_link_dummy" />
  <link name="right_arm_6_link">
    <inertial>
      <mass value="1.1" />
      <origin rpy="0 0 0" xyz="0 0 0.0625"/>
      <inertia ixx="0.00286458333333" ixy="0" ixz="0" iyy="0.00286458333333" iyz="0" izz="0.00286458333333" />
    </inertial>
    <visual>
      <origin rpy="0 0 3.14159265359" xyz="0 0 0"/>
      <geometry>
        <mesh filename=""/>
      </geometry>
      <material name="Kuka/Grey"/>
    </visual>
    <collision>
      <origin rpy="0 0 3.14159265359" xyz="0 -0.01 0"/>
      <geometry>
        <sphere radius="0.08"/>
      </geometry>
    </collision>
  </link>
  <!-- Eighth element of the arm. z-axis -->
  <joint name="right_arm_a6_joint" type="revolute">
    <origin rpy="0 0 0" xyz="0 0 0.078"/>
    <axis xyz="0 0 1"/>
    <limit effort="38" lower="-2.96705972839" upper="2.96705972839" velocity="3.21140582367"/>
    <dynamics damping="1.0" friction="10.0" />
    <parent link="right_arm_6_link"/>
    <child link="right_arm_7_link" />
  </joint>
  <joint name="right_arm_a6_joint_stiffness" type="revolute">
    <axis xyz="0 0 1"/>
    <limit effort="0" lower="0" upper="5000" velocity="20000"/>
    <safety_controller k_position="30" k_velocity="30" soft_lower_limit="0" soft_upper_limit="5000"/>
    <parent link="right_arm_6_link" />
    <child link="right_arm_7_link_dummy"/>
  </joint>
  <link name="right_arm_7_link_dummy" />
  <link name="right_arm_7_link">
    <inertial>
      <mass value="0.25" />
      <origin xyz="0 0 0"/>
      <inertia ixx="0.000416666666667" ixy="0" ixz="0" iyy="0.000416666666667" iyz="0" izz="0.000416666666667"/>
    </inertial>
    <visual>
      <origin rpy="0 0 3.14159265359" xyz="0 0 0"/>
      <geometry>
        <mesh filename=""/>
      </geometry>
      <material name="Kuka/DarkGrey"/>
    </visual>
    <collision>
      <origin rpy="0 0 3.14159265359" xyz="0 0 0"/>
      <geometry>
        <cylinder length="0.05" radius="0.04"/>
      </geometry>
    </collision>
  </link>

  <gazebo reference="right_arm_base_link">
    <gravity>true</gravity>
    <material>Gazebo/Orange</material>
  </gazebo>
  <gazebo reference="right_arm_a1_joint">
    <provideFeedback>true</provideFeedback>
  </gazebo>
  <gazebo reference="right_arm_1_link">
    <gravity>true</gravity>
    <material>Gazebo/Orange</material>
  </gazebo>
  <gazebo reference="right_arm_a2_joint">
    <provideFeedback>true</provideFeedback>
  </gazebo>
  <gazebo reference="right_arm_2_link">
    <gravity>true</gravity>
    <material>Gazebo/Orange</material>
  </gazebo>
  <gazebo reference="right_arm_e1_joint">
    <provideFeedback>true</provideFeedback>
  </gazebo>
  <gazebo reference="right_arm_3_link">
    <gravity>true</gravity>
    <material>Gazebo/Orange</material>
  </gazebo>
  <gazebo reference="right_arm_a3_joint">
    <provideFeedback>true</provideFeedback>
  </gazebo>
  <gazebo reference="right_arm_4_link">
    <gravity>true</gravity>
    <material>Gazebo/Orange</material>
  </gazebo>
  <gazebo reference="right_arm_a4_joint">
    <provideFeedback>true</provideFeedback>
  </gazebo>
  <gazebo reference="right_arm_5_link">
    <gravity>true</gravity>
    <material>Gazebo/Orange</material>
  </gazebo>
  <gazebo reference="right_arm_a5_joint">
    <provideFeedback>true</provideFeedback>
  </gazebo>
  <gazebo reference="right_arm_6_link">
    <gravity>true</gravity>
    <material>Gazebo/Orange</material>
  </gazebo>
  <gazebo reference="right_arm_a6_joint">
    <provideFeedback>true</provideFeedback>
  </gazebo>
  <gazebo reference="right_arm_7_link">
    <gravity>true</gravity>
    <material>Gazebo/Grey</material>
  </gazebo>
  <transmission name="right_arm_a1_trans">
    <type>transmission_interface/SimpleTransmission</type>
    <joint name="right_arm_a1_joint">
      <!-- <hardwareInterface>${Interface10}</hardwareInterface> -->
      <hardwareInterface>EffortJointInterface</hardwareInterface>
    </joint>
    <actuator name="right_arm_a1_motor">
      <mechanicalReduction>1</mechanicalReduction>
    </actuator>
  </transmission>
  <transmission name="right_arm_a2_trans">
    <type>transmission_interface/SimpleTransmission</type>
    <joint name="right_arm_a2_joint">
      <!-- <hardwareInterface>${Interface10}</hardwareInterface> -->
      <hardwareInterface>EffortJointInterface</hardwareInterface>
    </joint>
    <actuator name="right_arm_a2_motor">
      <mechanicalReduction>1</mechanicalReduction>
    </actuator>
  </transmission>
  <transmission name="right_arm_e1_trans">
    <type>transmission_interface/SimpleTransmission</type>
    <joint name="right_arm_e1_joint">
      <!-- <hardwareInterface>${Interface10}</hardwareInterface> -->
      <hardwareInterface>EffortJointInterface</hardwareInterface>
    </joint>
    <actuator name="right_arm_e1_motor">
      <mechanicalReduction>1</mechanicalReduction>
    </actuator>
  </transmission>
  <transmission name="right_arm_a3_trans">
    <type>transmission_interface/SimpleTransmission</type>
    <joint name="right_arm_a3_joint">
      <!-- <hardwareInterface>${Interface10}</hardwareInterface> -->
      <hardwareInterface>EffortJointInterface</hardwareInterface>
    </joint>
    <actuator name="right_arm_a3_motor">
      <mechanicalReduction>1</mechanicalReduction>
    </actuator>
  </transmission>
  <transmission name="right_arm_a4_trans">
    <type>transmission_interface/SimpleTransmission</type>
    <joint name="right_arm_a4_joint">
      <!-- <hardwareInterface>${Interface10}</hardwareInterface> -->
      <hardwareInterface>EffortJointInterface</hardwareInterface>
    </joint>
    <actuator name="right_arm_a4_motor">
      <mechanicalReduction>1</mechanicalReduction>
    </actuator>
  </transmission>
  <transmission name="right_arm_a5_trans">
    <type>transmission_interface/SimpleTransmission</type>
    <joint name="right_arm_a5_joint">
      <!-- <hardwareInterface>${Interface10}</hardwareInterface> -->
      <hardwareInterface>EffortJointInterface</hardwareInterface>
    </joint>
    <actuator name="right_arm_a5_motor">
      <mechanicalReduction>1</mechanicalReduction>
    </actuator>
  </transmission>
  <transmission name="right_arm_a6_trans">
    <type>transmission_interface/SimpleTransmission</type>
    <joint name="right_arm_a6_joint">
      <!-- <hardwareInterface>${Interface10}</hardwareInterface> -->
      <hardwareInterface>EffortJointInterface</hardwareInterface>
    </joint>
    <actuator name="right_arm_a6_motor">
      <mechanicalReduction>1</mechanicalReduction>
    </actuator>
  </transmission>
  <joint name="right_hand_ft_joint" type="fixed">
    <origin xyz="0 0 0.05"/>
    <parent link="right_arm_7_link" />
    <child link="right_hand_ft_link"/>
  </joint>
  <link name="right_hand_ft_link">
    <inertial>
      <origin xyz="0 0 0"/>
      <mass value="2"/>
      <inertia ixx="0.00161666666667" ixy="0" ixz="0" iyy="0.00161666666667" iyz="0" izz="0.0016"/>
    </inertial>
    <visual>
      <geometry>
        <cylinder length="0.10" radius="0.04"/>
      </geometry>
      <material name="DarkGrey"/>
    </visual>
    <collision>
      <geometry>
        <cylinder length="0.10" radius="0.04"/>
      </geometry>
    </collision>
  </link>
  <!-- joint between arm_7_link and sdh_palm_link -->
  <joint name="right_hand_palm_joint" type="fixed">
    <origin rpy="0 0 0" xyz="0 0 0.05" />
    <parent link="right_arm_7_link"/>
    <child link="right_hand_palm_link" />
  </joint>
  <link name="right_hand_palm_link">
    <inertial>
      <origin rpy="0 0 0" xyz="0 0 0"/>
      <mass value="1"/>
      <inertia ixx="0.01" ixy="0" ixz="0" iyy="0.01" iyz="0" izz="0.01"/>
    </inertial>
    <visual>
      <origin rpy="0 0 0" xyz="0 0 0"/>
      <geometry>
        <mesh filename=""/>
      </geometry>
      <material name="Schunk/LightGrey"/>
    </visual>
    <collision>
      <origin rpy="0 0 0" xyz="0 0 0"/>
      <geometry>
        <mesh filename=""/>
      </geometry>
    </collision>
  </link>
  <!-- grasp link -->
  <joint name="right_hand_grasp_joint" type="fixed">
    <origin rpy="0 0 0" xyz="0 0 0.15" />
    <parent link="right_hand_palm_link"/>
    <child link="right_hand_grasp_link" />
  </joint>
  <link name="right_hand_grasp_link"/>
  <!-- tip link -->
  <joint name="right_hand_tip_joint" type="fixed">
    <origin rpy="0 0 0" xyz="0 0 0.22"/>
    <parent link="right_hand_palm_link"/>
    <child link="right_hand_tip_link"/>
  </joint>
  <link name="right_hand_tip_link"/>
  <!-- finger1 -->
  <!-- joint between sdh_palm_link and sdh_finger_11_link -->
  <joint name="right_hand_knuckle_joint" type="revolute">
    <origin rpy="0 0 3.14159265" xyz="0.01905 0.033 0.0745"/>
    <parent link="right_hand_palm_link" />
    <child link="right_hand_finger_11_link"/>
    <axis xyz="0 0 1"/>
    <dynamics damping="0.7" friction="0"/>
    <limit effort="100" lower="0" upper="1.570796327" velocity="0.5"/>
  </joint>
  <link name="right_hand_finger_11_link">
    <inertial>
      <origin rpy="0 0 0" xyz="0 0 0"/>
      <mass value="0.1"/>
      <inertia ixx="0.01" ixy="0" ixz="0" iyy="0.01" iyz="0" izz="0.01"/>
    </inertial>
    <visual>
      <origin rpy="0 0 0" xyz="0 0 0"/>
      <geometry>
        <mesh filename=""/>
      </geometry>
      <material name="Schunk/LightGrey"/>
    </visual>
    <collision>
      <origin rpy="0 0 0" xyz="0 0 0"/>
      <geometry>
        <mesh filename=""/>
      </geometry>
    </collision>
  </link>
  <!-- joint between sdh_finger_11_link and sdh_finger_12_link -->
  <joint name="right_hand_finger_12_joint" type="revolute">
    <origin rpy="0 0 0" xyz="0 0 0.0165"/>
    <parent link="right_hand_finger_11_link"/>
    <child link="right_hand_finger_12_link"/>
    <axis xyz="0 1 0"/>
    <dynamics damping="0.7" friction="0"/>
    <limit effort="100" lower="-1.570796327" upper="1.570796327" velocity="0.5"/>
  </joint>
  <link name="right_hand_finger_12_link">
    <inertial>
      <origin rpy="0 0 0" xyz="0 0 0"/>
      <mass value="0.1"/>
      <inertia ixx="0.01" ixy="0" ixz="0" iyy="0.01" iyz="0" izz="0.01" />
    </inertial>
    <visual>
      <origin rpy="0 0 0" xyz="0 0 0"/>
      <geometry>
        <mesh filename=""/>
      </geometry>
      <material name="Schunk/LightGrey"/>
    </visual>
    <collision>
      <origin rpy="0 0 0" xyz="0 0 0"/>
      <geometry>
        <mesh filename=""/>
      </geometry>
    </collision>
  </link>
  <!-- joint between sdh_finger_12_link and sdh_finger_13_link -->
  <joint name="right_hand_finger_13_joint" type="revolute">
    <origin rpy="0 0 0" xyz="0 0 0.0865"/>
    <parent link="right_hand_finger_12_link"/>
    <child link="right_hand_finger_13_link"/>
    <axis xyz="0 1 0"/>
    <dynamics damping="0.7" friction="0"/>
    <limit effort="100" lower="-1.570796327" upper="1.570796327" velocity="0.5"/>
  </joint>
  <link name="right_hand_finger_13_link">
    <inertial>
      <origin rpy="0 0 0" xyz="0 0 0"/>
      <mass value="0.1"/>
      <inertia ixx="0.01" ixy="0" ixz="0" iyy="0.01" iyz="0" izz="0.01" />
    </inertial>
    <visual>
      <origin rpy="0 0 0" xyz="0 0 0"/>
      <geometry>
        <mesh filename=""/>
      </geometry>
      <material name="Schunk/LightGrey"/>
    </visual>
    <collision>
      <origin rpy="0 0 0" xyz="0 0 0"/>
      <geometry>
        <mesh filename=""/>
      </geometry>
    </collision>
  </link>
  <!-- finger2 -->
  <!-- joint between sdh_palm_link and sdh_finger_21_link -->
  <joint name="right_hand_finger_21_joint" type="revolute">
    <mimic joint="right_hand_knuckle_joint" multiplier="1" offset="0"/>
    <origin rpy="0 0 3.14159265" xyz="0.01905 -0.033 0.0745" />
    <parent link="right_hand_palm_link"/>
    <child link="right_hand_finger_21_link" />
    <axis xyz="0 0 -1"/>
    <dynamics damping="0.7" friction="0"/>
    <limit effort="100" lower="0" upper="1.570796327" velocity="0.5"/>
  </joint>
  <link name="right_hand_finger_21_link">
    <inertial>
      <origin rpy="0 0 0" xyz="0 0 0"/>
      <mass value="0.1"/>
      <inertia ixx="0.01" ixy="0" ixz="0" iyy="0.01" iyz="0" izz="0.01"/>
    </inertial>
    <visual>
      <origin rpy="0 0 0" xyz="0 0 0"/>
      <geometry>
        <mesh filename=""/>
      </geometry>
      <material name="Schunk/LightGrey"/>
    </visual>
    <collision>
      <origin rpy="0 0 0" xyz="0 0 0"/>
      <geometry>
        <mesh filename=""/>
      </geometry>
    </collision>
  </link>
  <!-- joint between sdh_finger_21_link and sdh_finger_22_link -->
  <joint name="right_hand_finger_22_joint" type="revolute">
    <origin rpy="0 0 0" xyz="0 0 0.0165"/>
    <parent link="right_hand_finger_21_link"/>
    <child link="right_hand_finger_22_link"/>
    <axis xyz="0 1 0"/>
    <dynamics damping="0.7" friction="0"/>
    <limit effort="100" lower="-1.570796327" upper="1.570796327" velocity="0.5"/>
  </joint>
  <link name="right_hand_finger_22_link">
    <inertial>
      <origin rpy="0 0 0" xyz="0 0 0"/>
      <mass value="0.1"/>
      <inertia ixx="0.01" ixy="0" ixz="0" iyy="0.01" iyz="0" izz="0.01" />
    </inertial>
    <visual>
      <origin rpy="0 0 0" xyz="0 0 0"/>
      <geometry>
        <mesh filename=""/>
      </geometry>
      <material name="Schunk/LightGrey"/>
    </visual>
    <collision>
      <origin rpy="0 0 0" xyz="0 0 0"/>
      <geometry>
        <mesh filename=""/>
      </geometry>
    </collision>
  </link>
  <!-- joint between sdh_finger_22_link and sdh_finger_23_link -->
  <joint name="right_hand_finger_23_joint" type="revolute">
    <origin rpy="0 0 0" xyz="0 0 0.0865"/>
    <parent link="right_hand_finger_22_link"/>
    <child link="right_hand_finger_23_link"/>
    <axis xyz="0 1 0"/>
    <dynamics damping="0.7" friction="0"/>
    <limit effort="100" lower="-1.570796327" upper="1.570796327" velocity="0.5"/>
  </joint>
  <link name="right_hand_finger_23_link">
    <inertial>
      <origin rpy="0 0 0" xyz="0 0 0"/>
      <mass value="0.1"/>
      <inertia ixx="0.01" ixy="0" ixz="0" iyy="0.01" iyz="0" izz="0.01" />
    </inertial>
    <visual>
      <origin rpy="0 0 0" xyz="0 0 0"/>
      <geometry>
        <mesh filename=""/>
      </geometry>
      <material name="Schunk/LightGrey"/>
    </visual>
    <collision>
      <origin rpy="0 0 0" xyz="0 0 0"/>
      <geometry>
        <mesh filename=""/>
      </geometry>
    </collision>
  </link>
  <!-- thumb -->
  <!-- joint between sdh_palm_link and sdh_thumb_1_link -->
  <joint name="right_hand_thumb_1_joint" type="fixed">
    <origin rpy="0 0 0" xyz="-0.03811 0 0.0745 "/>
    <parent link="right_hand_palm_link"/>
    <child link="right_hand_thumb_1_link"/>
  </joint>
  <link name="right_hand_thumb_1_link">
    <inertial>
      <origin rpy="0 0 0" xyz="0 0 0"/>
      <mass value="0.1"/>
      <inertia ixx="0.01" ixy="0" ixz="0" iyy="0.01" iyz="0" izz="0.01"/>
    </inertial>
    <visual>
      <origin rpy="0 0 0" xyz="0 0 0"/>
      <geometry>
        <mesh filename=""/>
      </geometry>
      <material name="Schunk/LightGrey"/>
    </visual>
    <collision>
      <origin rpy="0 0 0" xyz="0 0 0"/>
      <geometry>
        <mesh filename=""/>
      </geometry>
    </collision>
  </link>
  <!-- joint between sdh_thumb_1_link and shd_thumb_2_link -->
  <joint name="right_hand_thumb_2_joint" type="revolute">
    <origin rpy="0 0 0" xyz="0 0 0.0165"/>
    <parent link="right_hand_thumb_1_link" />
    <child link="right_hand_thumb_2_link"/>
    <axis xyz="0 1 0"/>
    <dynamics damping="0.7" friction="0"/>
    <limit effort="100" lower="-1.570796327" upper="1.570796327" velocity="0.5"/>
  </joint>
  <link name="right_hand_thumb_2_link">
    <inertial>
      <origin rpy="0 0 0" xyz="0 0 0"/>
      <mass value="0.1"/>
      <inertia ixx="0.01" ixy="0" ixz="0" iyy="0.01" iyz="0" izz="0.01"/>
    </inertial>
    <visual>
      <origin rpy="0 0 0" xyz="0 0 0"/>
      <geometry>
        <mesh filename=""/>
      </geometry>
      <material name="Schunk/LightGrey"/>
    </visual>
    <collision>
      <origin rpy="0 0 0" xyz="0 0 0"/>
      <geometry>
        <mesh filename=""/>
      </geometry>
    </collision>
  </link>
  <!-- joint between sdh_thumb_2_link and sdh_thumb_3_link -->
  <joint name="right_hand_thumb_3_joint" type="revolute">
    <origin rpy="0 0 0" xyz="0 0 0.0865"/>
    <parent link="right_hand_thumb_2_link" />
    <child link="right_hand_thumb_3_link"/>
    <axis xyz="0 1 0"/>
    <dynamics damping="0.7" friction="0"/>
    <limit effort="100" lower="-1.570796327" upper="1.570796327" velocity="0.5"/>
  </joint>
  <link name="right_hand_thumb_3_link">
    <inertial>
      <origin rpy="0 0 0" xyz="0 0 0"/>
      <mass value="0.1"/>
      <inertia ixx="0.01" ixy="0" ixz="0" iyy="0.01" iyz="0" izz="0.01"/>
    </inertial>
    <visual>
      <origin rpy="0 0 0" xyz="0 0 0"/>
      <geometry>
        <mesh filename=""/>
      </geometry>
      <material name="Schunk/LightGrey"/>
    </visual>
    <collision>
      <origin rpy="0 0 0" xyz="0 0 0"/>
      <geometry>
        <mesh filename=""/>
      </geometry>
    </collision>
  </link>

  <gazebo reference="right_hand_palm_link">
    <material>Schunk/LightGrey</material>
    <turnGravityOff>false</turnGravityOff>
  </gazebo>
  <gazebo reference="right_hand_finger_11_link">
    <material>Schunk/LightGrey</material>
    <turnGravityOff>false</turnGravityOff>
    <mu1>1000</mu1>
    <mu2>1000</mu2>
    <kp>1e5</kp>
    <kd>1.0</kd>
  </gazebo>
  <gazebo reference="right_hand_finger_12_link">
    <selfCollide>true</selfCollide>
    <sensor name="right_hand_finger_12_contact_sensor" type="contact">
      <always_on>true</always_on>
      <update_rate>100</update_rate>
      <contact>
        <collision>right_hand_finger_12_link_geom</collision>
      </contact>

    </sensor>
    <material>Schunk/LightGrey</material>
    <turnGravityOff>false</turnGravityOff>
    <mu1>1000</mu1>
    <mu2>1000</mu2>
    <kp>1e5</kp>
    <kd>1.0</kd>
  </gazebo>
  <gazebo reference="right_hand_finger_13_link">
    <selfCollide>true</selfCollide>
    <sensor name="right_hand_finger_13_contact_sensor" type="contact">
      <always_on>true</always_on>
      <update_rate>100</update_rate>
      <contact>
        <collision>right_hand_finger_13_link_geom</collision>
      </contact>

    </sensor>
    <material>Schunk/LightGrey</material>
    <mu1>1000</mu1>
    <mu2>1000</mu2>
    <kp>1e5</kp>
    <kd>1.0</kd>
  </gazebo>
  <gazebo reference="right_hand_finger_21_link">
    <material>Schunk/LightGrey</material>
    <turnGravityOff>false</turnGravityOff>
    <mu1>1000</mu1>
    <mu2>1000</mu2>
    <kp>1e5</kp>
    <kd>1.0</kd>
  </gazebo>
  <gazebo reference="right_hand_finger_22_link">
    <selfCollide>true</selfCollide>
    <sensor name="right_hand_finger_22_contact_sensor" type="contact">
      <always_on>true</always_on>
      <update_rate>100</update_rate>
      <contact>
        <collision>right_hand_finger_22_link_geom</collision>
      </contact>

    </sensor>
    <material>Schunk/LightGrey</material>
    <turnGravityOff>false</turnGravityOff>
    <mu1>1000</mu1>
    <mu2>1000</mu2>
    <kp>1e5</kp>
    <kd>1.0</kd>
  </gazebo>
  <gazebo reference="right_hand_finger_23_link">
    <selfCollide>true</selfCollide>
    <sensor name="right_hand_finger_23_contact_sensor" type="contact">
      <always_on>true</always_on>
      <update_rate>100</update_rate>
      <contact>
        <collision>right_hand_finger_23_link_geom</collision>
      </contact>

    </sensor>
    <material>Schunk/LightGrey</material>
    <mu1>1000</mu1>
    <mu2>1000</mu2>
    <kp>1e5</kp>
    <kd>1.0</kd>
  </gazebo>
  <gazebo reference="right_hand_thumb_1_link">
    <material>Schunk/LightGrey</material>
    <turnGravityOff>false</turnGravityOff>
    <mu1>1000</mu1>
    <mu2>1000</mu2>
    <kp>1e5</kp>
    <kd>1.0</kd>
  </gazebo>
  <gazebo reference="right_hand_thumb_2_link">
    <selfCollide>true</selfCollide>
    <sensor name="right_hand_thumb_2_contact_sensor" type="contact">
      <always_on>true</always_on>
      <update_rate>100</update_rate>
      <contact>
        <collision>right_hand_thumb_2_link_geom</collision>
      </contact>

    </sensor>
    <material>Schunk/LightGrey</material>
    <turnGravityOff>false</turnGravityOff>
    <mu1>1000</mu1>
    <mu2>1000</mu2>
    <kp>1e5</kp>
    <kd>1.0</kd>
  </gazebo>
  <gazebo reference="right_hand_thumb_3_link">
    <selfCollide>true</selfCollide>
    <sensor name="right_hand_thumb_3_contact_sensor" type="contact">
      <always_on>true</always_on>
      <update_rate>100</update_rate>
      <contact>
        <collision>right_hand_thumb_3_link_geom</collision>
      </contact>

    </sensor>
    <material>Schunk/LightGrey</material>
    <mu1>1000</mu1>
    <mu2>1000</mu2>
    <kp>1e5</kp>
    <kd>1.0</kd>
  </gazebo>
  <gazebo reference="right_hand_knuckle_joint">
    <implicitSpringDamper>1</implicitSpringDamper>
  </gazebo>
  <gazebo reference="right_hand_finger_12_joint">
    <implicitSpringDamper>1</implicitSpringDamper>
  </gazebo>
  <gazebo reference="right_hand_finger_13_joint">
    <implicitSpringDamper>1</implicitSpringDamper>
  </gazebo>
  <gazebo reference="right_hand_finger_21_joint">
    <implicitSpringDamper>1</implicitSpringDamper>
  </gazebo>
  <gazebo reference="right_hand_finger_22_joint">
    <implicitSpringDamper>1</implicitSpringDamper>
  </gazebo>
  <gazebo reference="right_hand_finger_23_joint">
    <implicitSpringDamper>1</implicitSpringDamper>
  </gazebo>
  <gazebo reference="right_hand_thumb_1_joint">
    <implicitSpringDamper>1</implicitSpringDamper>
  </gazebo>
  <gazebo reference="right_hand_thumb_2_joint">
    <implicitSpringDamper>1</implicitSpringDamper>
  </gazebo>
  <gazebo reference="right_hand_thumb_3_joint">
    <implicitSpringDamper>1</implicitSpringDamper>
  </gazebo>
  <!-- <transmission name="${name}_finger_21_trans">
      <type>transmission_interface/SimpleTransmission</type>
  			<joint name="${name}_finger_21_joint">
        <hardwareInterface>PositionJointInterface</hardwareInterface>
      </joint>
		  <actuator name="${name}_finger_21_motor">
			  <mechanicalReduction>1</mechanicalReduction>
      </actuator>
		</transmission> -->
  <transmission name="right_hand_knuckle_trans">
    <type>transmission_interface/SimpleTransmission</type>
    <joint name="right_hand_knuckle_joint">
      <hardwareInterface>EffortJointInterface</hardwareInterface>
    </joint>
    <actuator name="right_hand_knuckle_motor">
      <hardwareInterface>EffortJointInterface</hardwareInterface>
      <mechanicalReduction>1</mechanicalReduction>
    </actuator>
  </transmission>
  <!-- finger1 -->
  <transmission name="right_hand_finger_12_trans">
    <type>transmission_interface/SimpleTransmission</type>
    <joint name="right_hand_finger_12_joint">
      <hardwareInterface>EffortJointInterface</hardwareInterface>
    </joint>
    <actuator name="right_hand_finger_12_motor">
      <hardwareInterface>EffortJointInterface</hardwareInterface>
      <mechanicalReduction>1</mechanicalReduction>
    </actuator>
  </transmission>
  <transmission name="right_hand_finger_13_trans">
    <type>transmission_interface/SimpleTransmission</type>
    <joint name="right_hand_finger_13_joint">
      <hardwareInterface>EffortJointInterface</hardwareInterface>
    </joint>
    <actuator name="right_hand_finger_13_motor">
      <hardwareInterface>EffortJointInterface</hardwareInterface>
      <mechanicalReduction>1</mechanicalReduction>
    </actuator>
  </transmission>
  <!-- finger2 -->
  <transmission name="right_hand_finger_22_trans" type="pr2_mechfinger_21anism_model/SimpleTransmission">
    <type>transmission_interface/SimpleTransmission</type>
    finger_21
			
    <joint name="right_hand_finger_22_joint">
      <hardwareInterface>EffortJointInterface</hardwareInterface>
    </joint>
    <actuator name="right_hand_finger_22_motor">
      <hardwareInterface>EffortJointInterface</hardwareInterface>
      <mechanicalReduction>1</mechanicalReduction>
    </actuator>
  </transmission>
  <transmission name="right_hand_finger_23_trans">
    <type>transmission_interface/SimpleTransmission</type>
    <joint name="right_hand_finger_23_joint">
      <hardwareInterface>EffortJointInterface</hardwareInterface>
    </joint>
    <actuator name="right_hand_finger_23_motor">
      <hardwareInterface>EffortJointInterface</hardwareInterface>
      <mechanicalReduction>1</mechanicalReduction>
    </actuator>
  </transmission>
  <!-- thumb -->
  <transmission name="right_hand_thumb_2_trans">
    <type>transmission_interface/SimpleTransmission</type>
    <joint name="right_hand_thumb_2_joint">
      <hardwareInterface>EffortJointInterface</hardwareInterface>
    </joint>
    <actuator name="right_hand_thumb_2_motor">
      <hardwareInterface>EffortJointInterface</hardwareInterface>
      <mechanicalReduction>1</mechanicalReduction>
    </actuator>
  </transmission>
  <transmission name="right_hand_thumb_3_trans">
    <type>transmission_interface/SimpleTransmission</type>
    <joint name="right_hand_thumb_3_joint">
      <hardwareInterface>EffortJointInterface</hardwareInterface>
    </joint>
    <actuator name="right_hand_thumb_3_motor">
      <hardwareInterface>EffortJointInterface</hardwareInterface>
      <mechanicalReduction>1</mechanicalReduction>
    </actuator>
  </transmission>
  <gazebo reference="right_hand_palm_joint">
    <provideFeedback>true</provideFeedback>
    <disableFixedJointLumping>true</disableFixedJointLumping>
  </gazebo>

  <joint name="head_mount_joint_1" type="fixed">
    <origin rpy="0 0 0" xyz="-0.06 0 0.1625"/>
    <parent link="base_link"/>
    <child link="head_mount_link_1"/>
  </joint>
  <link name="head_mount_link_1">
    <inertial>
      <origin xyz="0 0 0"/>
      <mass value="2.0"/>
      <inertia ixx="0.02" ixy="0.0" ixz="0.0" iyy="0.02" iyz="0.0" izz="0.02"/>
    </inertial>
    <visual>
      <geometry>
        <box size="0.04 0.04 0.325"/>
      </geometry>
      <material name="LigthGrey"/>
    </visual>
    <collision>
      <geometry>
        <box size="0.04 0.04 0.325"/>
      </geometry>
    </collision>
  </link>
  <gazebo reference="head_mount_link_1">
    <!-- <selfCollide>true</selfCollide> -->
    <material>Gazebo/Grey</material>
  </gazebo>
  <joint name="head_mount_joint_2" type="fixed">
    <origin rpy="0 0 0" xyz="-0.22 0 0.1625"/>
    <parent link="base_link"/>
    <child link="head_mount_link_2"/>
  </joint>
  <link name="head_mount_link_2">
    <inertial>
      <origin xyz="0 0 0"/>
      <mass value="2.0"/>
      <inertia ixx="0.02" ixy="0.0" ixz="0.0" iyy="0.02" iyz="0.0" izz="0.02"/>
    </inertial>
    <visual>
      <geometry>
        <box size="0.04 0.04 0.325"/>
      </geometry>
      <material name="LigthGrey"/>
    </visual>
    <collision>
      <geometry>
        <box size="0.04 0.04 0.325"/>
      </geometry>
    </collision>
  </link>
  <gazebo reference="head_mount_link_2">
    <!-- <selfCollide>true</selfCollide> -->
    <material>Gazebo/Grey</material>
  </gazebo>
  <joint name="head_mount_joint_3" type="fixed">
    <origin rpy="0 0 0" xyz="-0.235 0 0.345"/>
    <parent link="base_link"/>
    <child link="head_mount_link_3"/>
  </joint>
  <link name="head_mount_link_3">
    <inertial>
      <origin xyz="0 0 0"/>
      <mass value="2.0"/>
      <inertia ixx="0.02" ixy="0.0" ixz="0.0" iyy="0.02" iyz="0.0" izz="0.02"/>
    </inertial>
    <visual>
      <geometry>
        <box size="0.41 0.04 0.04"/>
      </geometry>
      <material name="LigthGrey"/>
    </visual>
    <collision>
      <geometry>
        <box size="0.41 0.04 0.04"/>
      </geometry>
    </collision>
  </link>
  <gazebo reference="head_mount_link_3">
    <!-- <selfCollide>true</selfCollide> -->
    <material>Gazebo/Grey</material>
  </gazebo>
  <joint name="head_mount_joint_support_plate" type="fixed">
    <origin rpy="0 0 0" xyz="-0.124 0.0 0.371"/>
    <parent link="base_link"/>
    <child link="head_mount_link_support_plate"/>
  </joint>
  <link name="head_mount_link_support_plate">
    <inertial>
      <origin xyz="0 0 0"/>
      <mass value="2.0"/>
      <inertia ixx="0.02" ixy="0.0" ixz="0.0" iyy="0.02" iyz="0.0" izz="0.02"/>
    </inertial>
    <visual>
      <geometry>
        <box size="0.108 0.108 0.012"/>
      </geometry>
      <material name="LigthGrey"/>
    </visual>
    <collision>
      <geometry>
        <box size="0.108 0.108 0.012"/>
      </geometry>
    </collision>
  </link>
  <gazebo reference="head_mount_link_support_plate">
    <!-- <selfCollide>true</selfCollide> -->
    <material>Gazebo/Grey</material>
  </gazebo>
  <joint name="head_mount_joint_box" type="fixed">
    <origin rpy="0 0 0" xyz="-0.4 0 0.205"/>
    <parent link="base_link"/>
    <child link="head_mount_link_box"/>
  </joint>
  <link name="head_mount_link_box">
    <inertial>
      <origin xyz="0 0 0"/>
      <mass value="2.0"/>
      <inertia ixx="0.02" ixy="0.0" ixz="0.0" iyy="0.02" iyz="0.0" izz="0.02"/>
    </inertial>
    <visual>
      <geometry>
        <box size="0.24 0.1 0.24"/>
      </geometry>
      <material name="Black"/>
    </visual>
    <collision>
      <geometry>
        <box size="0.24 0.1 0.24"/>
      </geometry>
    </collision>
  </link>
  <gazebo reference="head_mount_link_box">
    <!-- <selfCollide>true</selfCollide> -->
    <material>Gazebo/Black</material>
  </gazebo>
  <!-- The base of the hand, fixed to its parent. -->
  <joint name="base_link_head_base_joint" type="fixed">
    <origin xyz="-0.169 0.0 0.437"/>
    <parent link="base_link" />
    <child link="head_base_link"/>
  </joint>
  <link name="head_base_link">
    <inertial>
      <origin xyz="0 0 0"/>
      <mass value="0.2"/>
      <inertia ixx="0.02" ixy="0.0" ixz="0.0" iyy="0.02" iyz="0.0" izz="0.02"/>
    </inertial>
    <!-- <visual>
        <origin xyz="0 0 0" rpy="0 0 0"/>
        <geometry>
          <cylinder radius="0.03" length="0.15" />
        </geometry>
        <material name="KIT/DarkGrey"/>
      </visual>
      <collision>
        <origin xyz="0 0 0" rpy="0 0 0"/>
        <geometry>
          <cylinder radius="0.03" length="0.15"/>
        </geometry>
      </collision> -->
  </link>
  <!-- neck -->
  <joint name="head_neck_pitch_joint" type="revolute">
    <origin rpy="-1.57079632679 0 0" xyz="0 0 0"/>
    <axis xyz="0 0 1"/>
    <limit effort="204" lower="-0.575958653158" upper="0.575958653158" velocity="3.14159265359"/>
    <safety_controller k_position="30" k_velocity="30" soft_lower_limit="-0.575958653158" soft_upper_limit="0.575958653158"/>
    <dynamics damping="1.0" friction="1.0"/>
    <parent link="head_base_link"/>
    <child link="head_head_1_link"/>
  </joint>
  <link name="head_head_1_link">
    <inertial>
      <origin xyz="0 0 0" />
      <mass value="0.2"/>
      <inertia ixx="0.02" ixy="0.0" ixz="0.0" iyy="0.02" iyz="0.0" izz="0.02"/>
    </inertial>
    <visual>
      <origin rpy="0 0 0" xyz="0 0 0"/>
      <geometry>
        <cylinder length="0.15" radius="0.03"/>
      </geometry>
      <material name="KIT/DarkGrey"/>
    </visual>
    <collision>
      <origin rpy="0 0 0" xyz="0 0 0"/>
      <geometry>
        <cylinder length="0.15" radius="0.03"/>
      </geometry>
    </collision>
  </link>
  <joint name="head_neck_roll_joint" type="revolute">
    <origin rpy="0 1.57079632679 0" xyz="0 0 0"/>
    <axis xyz="0 0 1"/>
    <limit effort="204" lower="-0.488692190558" upper="0.488692190558" velocity="3.14159265359"/>
    <safety_controller k_position="30" k_velocity="30" soft_lower_limit="-0.488692190558" soft_upper_limit="0.488692190558"/>
    <dynamics damping="1.0" friction="1.0"/>
    <parent link="head_head_1_link"/>
    <child link="head_head_2_link"/>
  </joint>
  <link name="head_head_2_link">
    <inertial>
      <origin xyz="0 0 0" />
      <mass value="0.2"/>
      <inertia ixx="0.02" ixy="0.0" ixz="0.0" iyy="0.02" iyz="0.0" izz="0.02"/>
    </inertial>
    <visual>
      <origin rpy="0 0 0" xyz="0 0 0"/>
      <geometry>
        <cylinder length="0.15" radius="0.03"/>
      </geometry>
      <material name="KIT/DarkGrey"/>
    </visual>
    <collision>
      <origin rpy="0 0 0" xyz="0 0 0"/>
      <geometry>
        <cylinder length="0.15" radius="0.03"/>
      </geometry>
    </collision>
  </link>
  <joint name="head_neck_yaw_joint" type="revolute">
    <origin rpy="-1.57079632679 -1.57079632679 0" xyz="0 0 0"/>
    <axis xyz="0 0 1"/>
    <limit effort="204" lower="-1.98967534727" upper="1.98967534727" velocity="3.14159265359"/>
    <safety_controller k_position="30" k_velocity="30" soft_lower_limit="-1.98967534727" soft_upper_limit="1.98967534727" />
    <dynamics damping="1.0" friction="1.0"/>
    <parent link="head_head_2_link" />
    <child link="head_head_3_link"/>
  </joint>
  <link name="head_head_3_link">
    <inertial>
      <origin xyz="0 0 0"/>
      <mass value="0.2"/>
      <inertia ixx="0.02" ixy="0.0" ixz="0.0" iyy="0.02" iyz="0.0" izz="0.02"/>
    </inertial>
    <visual>
      <origin rpy="0 0 0" xyz="0 0 0" />
      <geometry>
        <cylinder length="0.15" radius="0.03"/>
      </geometry>
      <material name="KIT/DarkGrey"/>
    </visual>
    <collision>
      <origin rpy="0 0 0" xyz="0 0 0"/>
      <geometry>
        <cylinder length="0.15" radius="0.03"/>
      </geometry>
    </collision>
  </link>
  <joint name="head_head_tilt_joint" type="revolute">
    <origin rpy="1.57079632679 0 0" xyz="0 0 -0.12"/>
    <axis xyz="0 0 1"/>
    <limit effort="204" lower="-0.698131700798" upper="0.698131700798" velocity="3.14159265359" />
    <safety_controller k_position="30" k_velocity="30" soft_lower_limit="-0.698131700798" soft_upper_limit="0.698131700798"/>
    <dynamics damping="1.0" friction="1.0"/>
    <parent link="head_head_3_link"/>
    <child link="head_head_4_link"/>
  </joint>
  <link name="head_head_4_link">
    <inertial>
      <origin xyz="0 0 0"/>
      <mass value="0.2"/>
      <inertia ixx="0.02" ixy="0.0" ixz="0.0" iyy="0.02" iyz="0.0" izz="0.02"/>
    </inertial>
    <visual>
      <origin rpy="0 0 0" xyz="0 0 0"/>
      <geometry>
        <cylinder length="0.15" radius="0.03"/>
      </geometry>
      <material name="KIT/DarkGrey"/>
    </visual>
    <collision>
      <origin rpy="0 0 0" xyz="0 0 0"/>
      <geometry>
        <cylinder length="0.15" radius="0.03"/>
      </geometry>
    </collision>
  </link>
  <joint name="head_eyes_tilt_joint" type="revolute">
    <origin rpy="0 0 0" xyz="0.1 -0.0545 0"/>
    <axis xyz="0 0 1"/>
    <limit effort="204" lower="-0.349065850399" upper="0.349065850399" velocity="3.14159265359"/>
    <safety_controller k_position="30" k_velocity="30" soft_lower_limit="-0.349065850399" soft_upper_limit="0.349065850399"/>
    <dynamics damping="1.0" friction="1.0"/>
    <parent link="head_head_4_link"/>
    <child link="head_head_5_link"/>
  </joint>
  <link name="head_head_5_link">
    <inertial>
      <origin xyz="0 0 0" />
      <mass value="0.2"/>
      <inertia ixx="0.02" ixy="0.0" ixz="0.0" iyy="0.02" iyz="0.0" izz="0.02"/>
    </inertial>
    <visual>
      <origin rpy="0 0 0" xyz="0 0 0"/>
      <geometry>
        <cylinder length="0.03" radius="0.03"/>
      </geometry>
      <material name="KIT/DarkGrey"/>
    </visual>
    <collision>
      <origin rpy="1.57079632679 0 0" xyz="-0.1 0.10 0"/>
      <geometry>
        <cylinder length="0.3" radius="0.12"/>
      </geometry>
    </collision>
  </link>
  <joint name="head_left_eye_joint" type="revolute">
    <origin rpy="1.57079632679 0 0" xyz="0 0 0.0465"/>
    <axis xyz="0 0 1"/>
    <limit effort="204" lower="-0.349065850399" upper="0.349065850399" velocity="3.14159265359"/>
    <safety_controller k_position="30" k_velocity="30" soft_lower_limit="-0.349065850399" soft_upper_limit="0.349065850399"/>
    <dynamics damping="1.0" friction="1.0"/>
    <parent link="head_head_5_link"/>
    <child link="head_left_eye_link"/>
  </joint>
  <link name="head_left_eye_link">
    <inertial>
      <origin xyz="0 0 0" />
      <mass value="0.2"/>
      <inertia ixx="0.02" ixy="0.0" ixz="0.0" iyy="0.02" iyz="0.0" izz="0.02"/>
    </inertial>
    <visual>
      <origin rpy="0 1.57079632679 0" xyz="0.02 0 0"/>
      <geometry>
        <cylinder length="0.02" radius="0.03"/>
      </geometry>
      <material name="KIT/White"/>
    </visual>
    <collision>
      <origin rpy="0 1.57079632679 0" xyz="0.02 0 0"/>
      <geometry>
        <cylinder length="0.02" radius="0.03"/>
      </geometry>
    </collision>
  </link>
  <joint name="head_right_eye_joint" type="revolute">
    <origin rpy="1.57079632679 0 0" xyz="0 0 -0.0465" />
    <axis xyz="0 0 1"/>
    <limit effort="204" lower="-0.349065850399" upper="0.349065850399" velocity="3.14159265359"/>
    <safety_controller k_position="30" k_velocity="30" soft_lower_limit="-0.349065850399" soft_upper_limit="0.349065850399"/>
    <dynamics damping="1.0" friction="1.0"/>
    <parent link="head_head_5_link"/>
    <child link="head_right_eye_link"/>
  </joint>
  <link name="head_right_eye_link">
    <inertial>
      <origin xyz="0 0 0"/>
      <mass value="0.2"/>
      <inertia ixx="0.02" ixy="0.0" ixz="0.0" iyy="0.02" iyz="0.0" izz="0.02"/>
    </inertial>
    <visual>
      <origin rpy="0 1.57079632679 0" xyz="0.02 0 0"/>
      <geometry>
        <cylinder length="0.02" radius="0.03"/>
      </geometry>
      <material name="KIT/White"/>
    </visual>
    <collision>
      <origin rpy="0 1.57079632679 0" xyz="0.02 0 0"/>
      <geometry>
        <cylinder length="0.02" radius="0.03"/>
      </geometry>
    </collision>
  </link>
  <!--     <joint name="${name}_face_joint" type="fixed">
      <origin xyz="0.05 -0.02 0" rpy="-1.57 2.356194 0.0" />
      <parent link="${name}_head_5_link"/>
      <child link="${name}_face_link"/>
    </joint>

    <link name="${name}_face_link">
      <visual>
        <origin xyz="0 0 0" rpy="0 0 0"/>
        <geometry>
<mesh filename=""/>
        </geometry>
        <material name="KIT/Orange"/>
      </visual>
      <collision>
        <origin xyz="0 0 0" rpy="0 0 0"/>
        <geometry>
          <cylinder radius="0.03" length="0.15"/>
        </geometry>
      </collision>
    </link> -->
  <joint name="head_asus_joint" type="fixed">
    <origin rpy="1.5707 0.0 0.0" xyz="0.062 -0.135 0.0"/>
    <parent link="head_head_4_link"/>
    <child link="head_asus_link"/>
  </joint>
  <link name="head_asus_link">
    <inertial>
      <origin xyz="0 0 0"/>
      <mass value="0.2"/>
      <inertia ixx="0.02" ixy="0.0" ixz="0.0" iyy="0.02" iyz="0.0" izz="0.02"/>
    </inertial>
    <visual>
      <origin rpy="0 0 0" xyz="0 0 0"/>
      <geometry>
        <mesh filename=""/>
      </geometry>
      <material name="KIT/Black"/>
    </visual>
    <collision>
      <origin rpy="1.57079632679 0 0" xyz="0 0 0"/>
      <geometry>
        <cylinder length="0.20" radius="0.03"/>
      </geometry>
    </collision>
  </link>
  <material name="aluminum">
    <color rgba="0.5 0.5 0.5 1"/>
  </material>
  <!-- camera body, with origin at bottom screw mount -->
  <joint name="head_realsense_camera_joint" type="fixed">
    <origin rpy="1.57079632679 0.0 0.0" xyz="0.082 -0.085 0.0"/>
    <parent link="head_head_4_link"/>
    <child link="head_realsense_camera_link"/>
  </joint>
  <link name="head_realsense_camera_link">
    <visual>
      <origin rpy="1.57079632679 0 1.57079632679" xyz="0.0149 0.0 0.0125"/>
      <geometry>
        <!-- <box size="${d435_cam_width} ${d435_cam_height} ${d435_cam_depth}"/> -->
        <mesh filename=""/>
      </geometry>
      <material name="aluminum"/>
    </visual>
    <collision>
      <origin rpy="0 0 0" xyz="0.0 0.0 0.0125"/>
      <geometry>
        <box size="0.02505 0.09 0.025"/>
      </geometry>
    </collision>
    <inertial>
      <!-- The following are not reliable values, and should not be used for modeling -->
      <mass value="0.564"/>
      <origin xyz="0 0 0"/>
      <inertia ixx="0.003881243" ixy="0.0" ixz="0.0" iyy="0.000498940" iyz="0.0" izz="0.003879257"/>
    </inertial>
  </link>
  <!-- camera depth joints and links -->
  <joint name="head_realsense_camera_depth_joint" type="fixed">
    <origin rpy="0 0 0" xyz="0.0149 0.0175 0.0125"/>
    <parent link="head_realsense_camera_link"/>
    <child link="head_realsense_camera_depth_frame" />
  </joint>
  <link name="head_realsense_camera_depth_frame"/>
  <joint name="head_realsense_camera_depth_optical_joint" type="fixed">
    <origin rpy="-1.57079632679 0 -1.57079632679" xyz="0 0 0"/>
    <parent link="head_realsense_camera_depth_frame" />
    <child link="head_realsense_camera_depth_optical_frame"/>
  </joint>
  <link name="head_realsense_camera_depth_optical_frame"/>
  <!-- camera left IR joints and links -->
  <joint name="head_realsense_camera_left_ir_joint" type="fixed">
    <origin rpy="0 0 0" xyz="0 0.0 0"/>
    <parent link="head_realsense_camera_depth_frame"/>
    <child link="head_realsense_camera_left_ir_frame" />
  </joint>
  <link name="head_realsense_camera_left_ir_frame"/>
  <joint name="head_realsense_camera_left_ir_optical_joint" type="fixed">
    <origin rpy="-1.57079632679 0 -1.57079632679" xyz="0 0 0"/>
    <parent link="head_realsense_camera_left_ir_frame" />
    <child link="head_realsense_camera_left_ir_optical_frame"/>
  </joint>
  <link name="head_realsense_camera_left_ir_optical_frame"/>
  <!-- camera right IR joints and links -->
  <joint name="head_realsense_camera_right_ir_joint" type="fixed">
    <origin rpy="0 0 0" xyz="0 -0.05 0"/>
    <parent link="head_realsense_camera_depth_frame"/>
    <child link="head_realsense_camera_right_ir_frame" />
  </joint>
  <link name="head_realsense_camera_right_ir_frame"/>
  <joint name="head_realsense_camera_right_ir_optical_joint" type="fixed">
    <origin rpy="-1.57079632679 0 -1.57079632679" xyz="0 0 0"/>
    <parent link="head_realsense_camera_right_ir_frame" />
    <child link="head_realsense_camera_right_ir_optical_frame"/>
  </joint>
  <link name="head_realsense_camera_right_ir_optical_frame"/>
  <!-- camera color joints and links -->
  <joint name="head_realsense_camera_color_joint" type="fixed">
    <origin rpy="0 0 0" xyz="0 0.015 0"/>
    <parent link="head_realsense_camera_depth_frame"/>
    <child link="head_realsense_camera_color_frame" />
  </joint>
  <link name="head_realsense_camera_color_frame"/>
  <joint name="head_realsense_camera_color_optical_joint" type="fixed">
    <origin rpy="-1.57079632679 0 -1.57079632679" xyz="0 0 0"/>
    <parent link="head_realsense_camera_color_frame" />
    <child link="head_realsense_camera_color_optical_frame"/>
  </joint>
  <link name="head_realsense_camera_color_optical_frame"/>
  <transmission name="head_neck_pitch_joint_trans">
    <type>transmission_interface/SimpleTransmission</type>
    <joint name="head_neck_pitch_joint">
      <hardwareInterface>PositionJointInterface</hardwareInterface>
    </joint>
    <actuator name="head_neck_pitch_joint_motor">
      <mechanicalReduction>1.0</mechanicalReduction>
    </actuator>
  </transmission>
  <transmission name="head_neck_roll_joint_trans">
    <type>transmission_interface/SimpleTransmission</type>
    <joint name="head_neck_roll_joint">
      <hardwareInterface>PositionJointInterface</hardwareInterface>
    </joint>
    <actuator name="head_neck_roll_joint_motor">
      <mechanicalReduction>1.0</mechanicalReduction>
    </actuator>
  </transmission>
  <transmission name="head_neck_yaw_joint_trans">
    <type>transmission_interface/SimpleTransmission</type>
    <joint name="head_neck_yaw_joint">
      <hardwareInterface>PositionJointInterface</hardwareInterface>
    </joint>
    <actuator name="head_neck_yaw_joint_motor">
      <mechanicalReduction>1.0</mechanicalReduction>
    </actuator>
  </transmission>
  <transmission name="head_head_tilt_joint_trans">
    <type>transmission_interface/SimpleTransmission</type>
    <joint name="head_head_tilt_joint">
      <hardwareInterface>PositionJointInterface</hardwareInterface>
    </joint>
    <actuator name="head_head_tilt_joint_motor">
      <mechanicalReduction>1.0</mechanicalReduction>
    </actuator>
  </transmission>
  <transmission name="head_eyes_tilt_joint_trans">
    <type>transmission_interface/SimpleTransmission</type>
    <joint name="head_eyes_tilt_joint">
      <hardwareInterface>PositionJointInterface</hardwareInterface>
    </joint>
    <actuator name="head_eyes_tilt_joint_motor">
      <mechanicalReduction>1.0</mechanicalReduction>
    </actuator>
  </transmission>
  <transmission name="head_left_eye_joint_trans">
    <type>transmission_interface/SimpleTransmission</type>
    <joint name="head_left_eye_joint">
      <hardwareInterface>PositionJointInterface</hardwareInterface>
    </joint>
    <actuator name="head_left_eye_joint_motor">
      <mechanicalReduction>1.0</mechanicalReduction>
    </actuator>
  </transmission>
  <transmission name="head_right_eye_joint_trans">
    <type>transmission_interface/SimpleTransmission</type>
    <joint name="head_right_eye_joint">
      <hardwareInterface>PositionJointInterface</hardwareInterface>
    </joint>
    <actuator name="head_right_eye_joint_motor">
      <mechanicalReduction>1.0</mechanicalReduction>
    </actuator>
  </transmission>
  <gazebo reference="head_base_link">
    <!-- selfCollide>true</selfCollide -->
    <gravity>true</gravity>
    <mu1>500.0</mu1>
    <mu2>500.0</mu2>
    <kp>10000000.0</kp>
    <kd>1.0</kd>
    <material>Gazebo/Grey</material>
  </gazebo>
  <gazebo reference="head_head_1_link">
    <!-- selfCollide>true</selfCollide -->
    <gravity>true</gravity>
    <mu1>500.0</mu1>
    <mu2>500.0</mu2>
    <kp>10000000.0</kp>
    <kd>1.0</kd>
    <material>Gazebo/Grey</material>
  </gazebo>
  <gazebo reference="head_head_2_link">
    <!-- selfCollide>true</selfCollide -->
    <gravity>true</gravity>
    <mu1>500.0</mu1>
    <mu2>500.0</mu2>
    <kp>10000000.0</kp>
    <kd>1.0</kd>
    <material>Gazebo/Grey</material>
  </gazebo>
  <gazebo reference="head_head_3_link">
    <!-- selfCollide>true</selfCollide -->
    <gravity>true</gravity>
    <mu1>500.0</mu1>
    <mu2>500.0</mu2>
    <kp>10000000.0</kp>
    <kd>1.0</kd>
    <material>Gazebo/Grey</material>
  </gazebo>
  <gazebo reference="head_head_4_link">
    <!-- selfCollide>true</selfCollide -->
    <gravity>true</gravity>
    <mu1>500.0</mu1>
    <mu2>500.0</mu2>
    <kp>10000000.0</kp>
    <kd>1.0</kd>
    <material>Gazebo/Grey</material>
  </gazebo>
  <gazebo reference="head_head_5_link">
    <!-- selfCollide>true</selfCollide -->
    <gravity>true</gravity>
    <mu1>500.0</mu1>
    <mu2>500.0</mu2>
    <kp>10000000.0</kp>
    <kd>1.0</kd>
    <material>Gazebo/Grey</material>
  </gazebo>
</robot>

