<robot name="chain2">
  <link name="link0"></link>
  <link name="link1"></link>
  <link name="link2"></link>

  <joint name="joint0" type="revolute">
    <parent link="link0"/>
    <child link="link1"/>
    <origin xyz="0.67 -0.78 -0.11" rpy="1.56 2.50 -1.87"/>
    <limit lower="-0.7467977126727877" upper="1.634520136596924" effort="0.0" velocity="0.0"/>
    <axis xyz="0 1 0"/>
  </joint>
  <joint name="joint1" type="prismatic">
    <parent link="link1"/>
    <child link="link2"/>
    <origin xyz="1.61 -1.40 -0.73" rpy="0.21 -0.01 0.03"/>
    <limit lower="-0.409708700339666" upper="0.19606005240497826" effort="0.0" velocity="0.0"/>
    <axis xyz="0 0 1"/>
  </joint></robot>