<robot name="chain6">
  <link name="link0"></link>
  <link name="link1"></link>
  <link name="link2"></link>
  <link name="link3"></link>
  <link name="link4"></link>
  <link name="link5"></link>
  <link name="link6"></link>

  <joint name="joint0" type="prismatic">
    <parent link="link0"/>
    <child link="link1"/>
    <origin xyz="1.56 -0.43 -1.01" rpy="3.03 -2.57 -0.30"/>
    <axis xyz="1 0 0"/>
  </joint>
  <joint name="joint1" type="revolute">
    <parent link="link1"/>
    <child link="link2"/>
    <origin xyz="1.14 -1.34 0.56" rpy="-1.41 -0.30 -0.15"/>
    <axis xyz="0 1 0"/>
  </joint>
  <joint name="joint2" type="revolute">
    <parent link="link2"/>
    <child link="link3"/>
    <origin xyz="0.96 -0.11 -1.14" rpy="1.42 -0.30 0.77"/>
    <axis xyz="0 0 1"/>
  </joint>
  <joint name="joint3" type="prismatic">
    <parent link="link3"/>
    <child link="link4"/>
    <origin xyz="-1.41 -0.08 1.51" rpy="-2.62 -2.07 2.97"/>
    <axis xyz="0 0 1"/>
  </joint>
  <joint name="joint4" type="prismatic">
    <parent link="link4"/>
    <child link="link5"/>
    <origin xyz="1.79 0.94 1.56" rpy="0.28 -2.27 -2.45"/>
    <axis xyz="1 0 0"/>
  </joint>
  <joint name="joint5" type="revolute">
    <parent link="link5"/>
    <child link="link6"/>
    <origin xyz="1.00 1.33 1.40" rpy="1.24 -1.72 -3.08"/>
    <axis xyz="1 0 0"/>
  </joint></robot>