<robot name="chain6">
  <link name="link0"></link>
  <link name="link1"></link>
  <link name="link2"></link>
  <link name="link3"></link>
  <link name="link4"></link>
  <link name="link5"></link>
  <link name="link6"></link>

  <joint name="joint0" type="prismatic">
    <parent link="link0"/>
    <child link="link1"/>
    <origin xyz="-1.65 0.15 -1.99" rpy="-0.07 1.17 2.16"/>
    <limit lower="-0.6939597249482587" upper="0.49741024074612594" effort="0.0" velocity="0.0"/>
    <axis xyz="0 1 0"/>
  </joint>
  <joint name="joint1" type="revolute">
    <parent link="link1"/>
    <child link="link2"/>
    <origin xyz="-1.74 -1.26 -1.93" rpy="2.98 1.18 1.66"/>
    <limit lower="-1.2323281494491418" upper="2.9138689589681546" effort="0.0" velocity="0.0"/>
    <axis xyz="1 0 0"/>
  </joint>
  <joint name="joint2" type="revolute">
    <parent link="link2"/>
    <child link="link3"/>
    <origin xyz="-1.75 -1.18 0.28" rpy="2.25 2.64 -0.30"/>
    <limit lower="-0.16045891452798122" upper="0.8482404436144259" effort="0.0" velocity="0.0"/>
    <axis xyz="0 1 0"/>
  </joint>
  <joint name="joint3" type="continuous">
    <parent link="link3"/>
    <child link="link4"/>
    <origin xyz="0.57 0.75 -1.04" rpy="1.86 -2.70 -2.22"/>
    <limit   effort="0.0" velocity="0.0"/>
    <axis xyz="0 0 1"/>
  </joint>
  <joint name="joint4" type="continuous">
    <parent link="link4"/>
    <child link="link5"/>
    <origin xyz="0.83 -1.22 -1.94" rpy="0.86 1.17 0.58"/>
    <limit   effort="0.0" velocity="0.0"/>
    <axis xyz="0 1 0"/>
  </joint>
  <joint name="joint5" type="prismatic">
    <parent link="link5"/>
    <child link="link6"/>
    <origin xyz="-0.29 1.87 -1.45" rpy="1.58 -0.52 1.03"/>
    <limit lower="-0.6791673519998924" upper="0.32489354914652224" effort="0.0" velocity="0.0"/>
    <axis xyz="0 1 0"/>
  </joint></robot>